Workbook
Name ang: CS!#REF!
Name ang: EN!#REF!
Name nem: DE!#REF!
Name OLE_LINK1: RU!#REF!
Name OLE_LINK11: A0!$C$93
Name OLE_LINK2: Czas!$A$76
Name OLE_LINK6: A0!$C$78
Name pol: PL!#REF!
Name rus: RU!#REF!

Sheet A0
B1: Stanisław Lem Non Fiction
B2: Bibliografia, Personalie
B3: Ułożył Wiktor Jaźniewicz
B4: Wersja od 15.07.2024 r. (Fragment "Dialogi")
B6: Ta książka stwarza się w systemie Microsoft Excel (z szerokim wykorzystaniem odsyłaczy),
B7: a następnie konwertowana do formatu Word .DOC i .PDF.
B8: W niniejszym pliku znajdują się następujące strony:
A9: - | B9: PL - Bibliografia w części monografii Lema "Dialogi" (wszystkie wydania łącznie z publikacją fragmentów)
A10: - | B10: RU, DE, EN, SK, CS, RO, NL, BE, MK - bibliografia tłumaczeń "Dialogów" (całości i fragmentów) odpowiednio w językach
B11: rosyjskim, niemieckim, angielskim, słowackim, czeskim, rumuńskim, niderlandzkim, białoruskim, macedońskim.
A12: - | B12: LO - listy otwarte i apele podpisane przez Lema.
A13: - | B13: My - maszynopisy (rękopisy) Lema przechowywane w archiwach.
A14: - | B14: About - książki, specjalne wydania czasopism i najważniejsze artykuły o Lemie.
A15: - | B15: PLF - bibliografia beletrystyki Lema.
A16: - | B16: PLp - Indeks person wydawniczy (współautorzy, rozmówcy, tłumacze, świadkowie wypowiedzi,
B17: redaktorzy książek i specjalnych czasopismów z artykułami Stanisława Lema i o nim, autorzy artykułów o Stanisławie Lemie).
A18: - | B18: Prs - Personalie Stanisława Lema (persony, wymienione w jego dziełach).
A19: - | B19: Wyd - wydawnictwa, które publikowały książki z dziełami Lema (we wszystkich językach).
A20: - | B20: INM - indeks monografii naukowych Lema (wydania we wszystkich językach).
A21: - | B21: Czas - indeks gazet i czasopism, które publikowały dzieła Lema (we wszystkich językach).
B22: Istnieje również plik o podobnej strukturze, zawierający bibliografię Wierszy Lema (we wszystkich językach).
B24: Zwróćcie uwagę!
B25: Odnośniki (po znaku "=" w zapisie bibliograficznym) podają się tak:
B26: aB:C.De, gdzie:
B27: a | C27: – | D27: ↑ czy ↓ (podaje się tylko na przodu dla listy odnośników) i oznacza odnośniki:
B28: ↑ | C28: – | D28: w każdym języku na pierwszą publikacje; dla pierwszego tłumaczenia na oryginał.
B29: ↓ | C29: – | D29: dla pierwszej publikacji (oryginała) na wszystkie następne publikacje.
B30: B: | C30: – | D30: rozdział (język) bibliografii (PL, BG, CZ itd). Nie podaje się przy odnośniku w ramach rozdziału (języka).
B31: C | C31: – | D31: numer publikacji w ramach danego rozdziała (języka).
B32: .D | C32: – | D32: numer tytuła w ramach publikacji. Nie podaje się przy jednym tytule w publikacji.
B33: e | C33: – | D33: -, <, > czy ! (nie podaje się, jeżeli następna publikacja całkiem odpowiada oryginału) i oznacza, że:
B34: - | C34: – | D34: następna publikacja jest w fragmencie (fragmentach) (zawiera mniej niż 50% oryginału).
B35: > | C35: – | D35: następna publikacja jest w skrócie (ale zawiera więcej niż 50% oryginału).
B36: < | C36: – | D36: następna publikacja jest poszerzona.
B37: ! | C37: – | D37: następna publikacja jest nieznacznie zmieniona.
B38: + | C38: – | D38: zjednoczenie publikacji
... B42: ¤ | C42: – | D42: publikacja z karykaturą S.Lema
B44: Odnośniki w Indeksach: B:C.D (patrz wyżej). Puste "B:" oznacza odnośnik na rozdział "PL".
B46: Odnośniki w "Personalie Stanisława Lema":
B47: Dla każdej osoby po znaku „–” znajduje się lista publikacji, w których osoba jest wymieniona.
...

Sheet PL
A1: PL: | B1: PL: Po polsku | C1: @ | D1: 2192 | E1: numb | F1: . | G1: „” | H1: , | I1: PL | J1: . – | K1: wydawca | L1: , | M1: rok, nr, s. □⌂¤ | N1: = | O1: ↓↑ | P1: ; | Q1: ↓↑tłumaczenia | R1: .
B2: * | I2: I. Monografie, artykuły, wywiady, listy, wypowiedzi
D3: ~~~~~~ | I3: Język Polski; Polish (PL)
D4: (…)
B5: a+k | C5: @ | D5: 101 | F5: . | G5: Lem S. | H5: , | I5: Dialog o wskrzeszaniu z atomów | J5: . – | K5: Nowa Kultura (W.) | L5: , | M5: 1957, nr 3, s.4-5. | N5: = | Q5: =CONCATENATE("↓",D6,".",E8) -> ↓126.1 | R5: .
B6: k+k* | C6: @ | D6: 126 | F6: . | G6: Lem S. | H6: , | I6: Dialogi: O zmartwychwstaniu atomowym, teorii niemożności, filozoficznych korzyściach ludożerstwa, smutku w próbówce, psychoanalizie cybernetycznej, elektrycznej metampsychozie, sprzężeniach zwrotnych ewolucji, eschatologii cybernetycznej, osobowości sieci elektrycznych, przewrotności elektromózgów, życiu wiecznym w skrzyni, konstruowaniu geniuszów, epilepsji kapitalizmu, maszynach do rządzenia, projektowaniu systemów społecznych | J6: . – | K6: K.: Wydawnictwo Literackie | L6: , | M6: 1957, 323 s. | N6: = | Q6: =CONCATENATE("↓",CS!A1,CS!D4,".",CS!E6,"; ",EN!A1,EN!D9,".",EN!E11,", ",EN!D13,".",EN!E15,", ",EN!D17,".",EN!E20,"; ",RO!A1,RO!D4,".",RO!E6) -> ↓CS:22.2; EN:158.6, 171.4, 172a.4; RO:3.1 | R6: .
D7: ~~~ | I7: Spis treści:
D8: ~~~ | E8: 1 | F8: . | I8: I | L8: , | M8: s.5-30. | N8: = | O8: =CONCATENATE("↑",D5) -> ↑101 | P8: ; | Q8: =CONCATENATE("↓",D19,".",E21,", ",D38,", ",D53,".",E54,", ",D62,".",E63,"; ",DE!A1,DE!D4,".",DE!E6,"; ",EN!A1,EN!D4,".",EN!E7,"; ",RU!A1,RU!D5,", ",RU!D12,", ",RU!D13,".",RU!E16,"; ",SK!A1,SK!D4,".",SK!E6,".") -> ↓361.1, 643a, 1944.1, 2141.1; DE:176.1; EN:152a.25; RU:177, 453, 478.2.1; SK:9.2.
D9: ~~~ | E9: 2 | F9: . | I9: II | L9: , | M9: s.31-44. | N9: = | Q9: =CONCATENATE("↓",D19,".",E22,", ",D57,".",E60,"; ",DE!A1,DE!D4,".",DE!E7,"; ",RU!A1,RU!D13,".",RU!E17,"; ",SK!A1,SK!D4,".",SK!E6) -> ↓361.2, 2126.10; DE:176.2; RU:478.2.2; SK:9.2 | R9: .
D10: ~~~ | E10: 3 | F10: . | I10: III | L10: , | M10: s.45-73. | N10: = | Q10: =CONCATENATE("↓",D19,".",E22,"; ",DE!A1,DE!D4,".",DE!E8,"; ",RU!A1,RU!D13,".",RU!E18,"; ",SK!A1,SK!D4,".",SK!E6) -> ↓361.2; DE:176.3; RU:478.2.3; SK:9.2 | R10: .
D11: ~~~ | E11: 4 | F11: . | I11: IV | L11: , | M11: s.74-100. | N11: = | Q11: =CONCATENATE("↓",D19,".",E22,", ",D62,".",E64,"; ",DE!A1,DE!D4,".",DE!E9,"; ",RU!A1,RU!D13,".",RU!E19,"; ",SK!A1,SK!D4,".",SK!E6) -> ↓361.2, 2141.2; DE:176.4; RU:478.2.4; SK:9.2 | R11: .
D12: ~~~ | E12: 5 | F12: . | I12: V | L12: , | M12: s.101-156. | N12: = | Q12: =CONCATENATE("↓",D19,".",E22,", ",D62,".",E65,"; ",DE!A1,DE!D4,".",DE!E10,"; ",RU!A1,RU!D13,".",RU!E20,"; ",SK!A1,SK!D4,".",SK!E6) -> ↓361.2, 2141.3; DE:176.5; RU:478.2.5; SK:9.2 | R12: .
D13: ~~~ | E13: 6 | F13: . | I13: VI | L13: , | M13: s.157-183. | N13: = | Q13: =CONCATENATE("↓",D19,".",E22,"; ",DE!A1,DE!D4,".",DE!E11,"; ",RU!A1,RU!D13,".",RU!E21,"; ",SK!A1,SK!D4,".",SK!E6) -> ↓361.2; DE:176.6; RU:478.2.6; SK:9.2 | R13: .
D14: ~~~ | E14: 7 | F14: . | I14: VII | L14: , | M14: s.184-264. | N14: = | Q14: =CONCATENATE("↓",D19,".",E22,"; ",DE!A1,DE!D4,".",DE!E12,"; ",RU!A1,RU!D3,", ",RU!D4,", ",RU!D13,".",RU!E22,"; ",SK!A1,SK!D4,".",SK!E6) -> ↓361.2; DE:176.7; RU:1, 137, 478.2.7; SK:9.2 | R14: .
D15: ~~~ | E15: 8 | F15: . | I15: VIII | L15: , | M15: s.265-314. | N15: = | Q15: =CONCATENATE("↓",D19,".",E22,", ",D68,".",E69,"; ",DE!A1,DE!D4,".",DE!E13,"; ",RU!A1,RU!D13,".",RU!E23) -> ↓361.2, 2192.1; DE:176.8; RU:478.2.8 | R15: .
B16: a+* | D16: ~~~ | E16: 9 | F16: . | I16: Przypisy | L16: , | M16: s.315-323.
B17: a176+k | C17: @ | D17: 305 | F17: . | G17: Lem S. | H17: , | I17: Etyka technologii i technologia etyki | J17: . – | K17: Studia Filozoficzne (W.) | L17: , | M17: 1967, nr 3, s.107-142. | N17: = | Q17: =CONCATENATE("↓",D19,".",E27,"; ",DE!A1,DE!D30,".",DE!E32,", ",DE!D51,"; ",RU!A1,RU!D6,".",RU!E7) -> ↓361.4.1; DE:281.2, 318; RU:182.1 | R17: .
B18: a178+k | C18: @ | D18: 312 | F18: . | G18: Lem S. | H18: , | I18: Biologia i wartości | J18: . – | K18: Studia Filozoficzne (W.) | L18: , | M18: 1968, nr 3/4, s.35-78. | N18: = | Q18: =CONCATENATE("↓",D19,".",E28) -> ↓361.4.2 | R18: .
C19: @ | D19: 361 | F19: . | G19: Lem S. | H19: , | I19: Dialogi | J19: . – | K19: K.: Wydawnictwo Literackie | L19: , | M19: 1972, 424 s. Wyd.2. | N19: = | Q19: =CONCATENATE("↓",BE!A1,BE!D4,".",BE!E6,"; ",EN!A1,EN!D17,".",EN!E18,", ",EN!D22,"; ",MK!A1,MK!D4,".",MK!E6) -> ↓BE:11.2.5; EN:172a.1, 177; MK:3.2.5 | R19: .
D20: ~~~ | I20: Spis treści:
B21: k+* | D21: ~~~ | E21: 1 | F21: . | I21: Przedmowa do drugiego wydania | L21: , | M21: s.5-7. | N21: = | Q21: =CONCATENATE("↓",D29,".",E30,"; ",RU!A1,RU!D13,".",RU!E14,"; ",SK!A1,SK!D4,".",SK!E5) -> ↓539.1; RU:478.1; SK:9.1 | R21: .
B22: k+c | D22: ~~~ | E22: 2 | F22: . | I22: Dialogi I-VIII | L22: , | M22: s.9-242. | N22: = | O22: =CONCATENATE("↑",D6,".",E8,"÷",E15) -> ↑126.1÷8 | P22: ; | Q22: =CONCATENATE("↓",D29,".",E31) -> ↓539.2 | R22: .
D23: ~~~ | E23: 3 | F23: . | I23: Aneks, część I: Dialogi po szesnastu latach
B24: k+* | D24: ~~~~~~ | E24: 3.1 | F24: . | I24: Tracone złudzenia, czyli od intelektroniki do informatyki | L24: , | M24: s.245-275. | N24: = | Q24: =CONCATENATE("↓",D29,".",E33,"; ",DE!A1,DE!D24,".",DE!E26,"; ",RU!A1,RU!D13,".",RU!E25) -> ↓539.3.1; DE:205.11; RU:478.3.1 | R24: .
B25: k+* | D25: ~~~~~~ | E25: 3.2 | F25: . | I25: Cybernetyka stosowana: przykład z dziedziny socjologii | L25: , | M25: s.276-300. | N25: = | Q25: =CONCATENATE("↓",D29,".",E34,"; ",DE!A1,DE!D24,".",DE!E28,"; ",RU!A1,RU!D13,".",RU!E26) -> ↓539.3.2; DE:205.13; RU:478.3.2 | R25: .
D26: ~~~ | E26: 4 | F26: . | I26: Aneks, część II
B27: k+* | D27: ~~~~~~ | E27: 4.1 | F27: . | I27: Etyka technologii i technologia etyki | L27: , | M27: s.303-356. | N27: = | O27: =CONCATENATE("↑",D17) -> ↑305 | P27: ; | Q27: =CONCATENATE("↓",D29,".",E36,"; ",RU!A1,RU!D13,".",RU!E28) -> ↓539.4.1; RU:478.4.1 | R27: .
B28: k+* | D28: ~~~~~~ | E28: 4.2 | F28: . | I28: Biologia i wartości | L28: , | M28: s.357-422. | N28: = | O28: =CONCATENATE("↑",D18) -> ↑312 | P28: ; | Q28: =CONCATENATE("↓",D29,".",E37,"; ",DE!A1,DE!D24,".",DE!E27,"; ",RU!A1,RU!D13,".",RU!E29) -> ↓539.4.2; DE:205.12; RU:478.4.2 | R28: .
B29: k+c | C29: @ | D29: 539 | F29: . | G29: Lem S. | H29: , | I29: Dialogi | J29: . – | K29: K., Wr.: Wydawnictwo Literackie | L29: , | M29: 1984, 504 s. Wyd.3.
D30: ~~~ | E30: 1 | F30: . | I30: Przedmowa do drugiego wydania | L30: , | M30: s.5-8. | N30: = | O30: =CONCATENATE("↑",D19,".",E21) -> ↑361.1 | P30: ; | Q30: =CONCATENATE("↓",D39,".",E41) -> ↓1025.1 | R30: .
D31: ~~~ | E31: 2 | F31: . | I31: Dialogi I-VIII | L31: , | M31: s.9-287. | N31: = | O31: =CONCATENATE("↑",D19,".",E22) -> ↑361.2 | P31: ; | Q31: =CONCATENATE("↓",D39,".",E42) -> ↓1025.2 | R31: .
D32: ~~~ | E32: 3 | F32: . | I32: Aneks, część I: Dialogi po szesnastu latach
D33: ~~~~~~ | E33: 3.1 | F33: . | I33: Tracone złudzenia, czyli od intelektroniki do informatyki | L33: , | M33: s.291-327. | N33: = | O33: =CONCATENATE("↑",D19,".",E24) -> ↑361.3.1 | P33: ; | Q33: =CONCATENATE("↓",D43,".",E46) -> ↓1026.1 | R33: .
D34: ~~~~~~ | E34: 3.2 | F34: . | I34: Cybernetyka stosowana: przykład z dziedziny socjologii | L34: , | M34: s.328-357. | N34: = | O34: =CONCATENATE("↑",D19,".",E25) -> ↑361.3.2 | P34: ; | Q34: =CONCATENATE("↓",D43,".",E47) -> ↓1026.2 | R34: .
D35: ~~~ | E35: 4 | F35: . | I35: Aneks, część II
D36: ~~~~~~ | E36: 4.1 | F36: . | I36: Etyka technologii i technologia etyki | L36: , | M36: s.362-425. | N36: = | O36: =CONCATENATE("↑",D19,".",E27) -> ↑361.4.1 | P36: ; | Q36: =CONCATENATE("↓",D43,".",E49) -> ↓1026.3 | R36: .
D37: ~~~~~~ | E37: 4.2 | F37: . | I37: Biologia i wartości | L37: , | M37: s.426-503. | N37: = | O37: =CONCATENATE("↑",D19,".",E28) -> ↑361.4.2 | P37: ; | Q37: =CONCATENATE("↓",D43,".",E50) -> ↓1026.4 | R37: .
B38: kc+ | C38: @ | D38: 643a | F38: . | G38: Lem S. | H38: , | I38: Dialogi. I / W: Aneksy (do Logiki zdrowego rozsądku) | J38: . – | K38: Darmstadt: Technische Hochschule | L38: , | M38: 1991(?), s.1-37. | N38: = | O38: =CONCATENATE("↑",D6,".",E8) -> ↑126.1 | R38: .
B39: k+c | C39: @ | D39: 1025 | F39: . | G39: Lem S. | H39: , | I39: Dialogi. T.1 | J39: . – | K39: W.: Interart | L39: , | M39: 1996, 288 s.□ [Wyd.4] | N39: = | Q39: =CONCATENATE("↓",D52) -> ↓1510 | R39: .
D40: ~~~ | I40: Spis treści:
...

Sheet RU
A1: RU: | C1: @ | D1: . | E1: numb | F1: . | G1: «» | H1: , | I1: RU | J1: . – | K1: wydawca | L1: , | M1: rok, nr, s. | N1: = | O1: ↓↑ | P1: ; | Q1: ↓↑tł | R1: . | S1: pierwodruk | T1: com | U1: 1 | V1: 2 | W1: 3 | X1: 4 | Y1: 5 | Z1: 6 | AA1: 7 | AB1: 8
B2: * | D2: ~~~~~~ | I2: Język Rosyjski; Русский язык; Russian (RU)
C3: @ | D3: 1 | F3: . | G3: Лем Станислав | H3: , | I3: Диалоги (фрагменты) / В статье: Николаев Н.Н., Рецензия на «С.Лем, Диалоги. Краков, 1957» | J3: . – | K3: Вопросы философии (М.) | L3: , | M3: 1958, №8, с.179-180. | N3: = | O3: =CONCATENATE("↑",PL!A1,PL!D6,".",PL!E14,"-") -> ↑PL:126.7- | R3: .
C4: @ | D4: 137 | F4: . | G4: Лем С. | H4: , | I4: Проект совершенного общества / Перевод с польского Э.Левина | J4: . – | K4: Страна и мир (Мюнхен) | L4: , | M4: 1987, №6, с.92-102. | N4: = | O4: =CONCATENATE("↑",PL!A1,PL!D6,".",PL!E14,">") -> ↑PL:126.7> | R4: .
C5: @ | D5: 177 | F5: . | G5: Лем С. | H5: , | I5: О воскрешении из атомов / Пер. К.Душенко | J5: . – | K5: Фантакрим-MEGA (Минск) | L5: , | M5: 1992, №5, с.48-50. | N5: = | O5: =CONCATENATE("↑",PL!A1,PL!D6,".",PL!E8,">") -> ↑PL:126.1> | R5: .
C6: @ | D6: 182 | F6: . | G6: Лем С. | H6: , | I6: Этика технологии и технология этики. Модель культуры / Составление, предисловие и перевод с польского К.В.Душенко; ред. В.Борисов | J6: . – | K6: Пермь: РИФ «Бегемот»; Абакан: ТОО «Центавр»; М.: Лаборатория теории и истории культуры ИНИОН РАН | L6: , | M6: 1993, 95 с. Содержание:
D7: ~~~ | E7: 1 | F7: . | I7: Этика технологии и технология этики | N7: = | O7: =CONCATENATE("↑",PL!A1,PL!D17) -> ↑PL:305 | R7: .
D8: ~~~~~~ | E8: 1.1 | F8: . | I8: Вступительные замечания | L8: , | M8: с.6-8.
D9: ~~~~~~ | E9: 1.2 | F9: . | I9: I | L9: , | M9: с.8-17.
D10: ~~~~~~ | E10: 1.3 | F10: . | I10: II | L10: , | M10: с.17-42.
D11: ~~~~~~ | E11: 1.4 | F11: . | I11: Резюме | L11: , | M11: с.42-46.
C12: @ | D12: 453 | F12: . | G12: Лем С. | H12: , | I12: Диалоги [I] / Пер. О.Салнит | J12: . – | K12: Известия (М.) | L12: , | M12: 2004, №235, 17 декабря 2004, с.45 (Чтение) | N12: = | Q12: =CONCATENATE("↓",D13,".",E16) -> ↓478.2.1 | R12: .
C13: @ | D13: 478 | F13: . | G13: Лем С. | H13: , | I13: Диалоги / Пер. О.Салнит; Науч. ред. Б.Старостин | J13: . – | K13: М.: ООО «Издательство АСТ»; ООО «Транзиткнига» | L13: , | M13: 2005, 523 с. (Philosophy). Содержание:
D14: ~~~ | E14: 1 | F14: . | I14: Предисловие | L14: , | M14: с.5-8. | N14: = | O14: =CONCATENATE("↑",PL!A1,PL!D19,".",PL!E21) -> ↑PL:361.1 | R14: .
D15: ~~~ | E15: 2 | F15: . | I15: Диалоги | X15: Мир, затаив дыхание, следит за судьбами украинского бунта…
D16: ~~~~~~ | E16: 2.1 | F16: . | I16: I | L16: , | M16: с.11-35. | N16: = | O16: =CONCATENATE("↑",D12,"<","; ",PL!A1,PL!D6,".",PL!E8) -> ↑453<; PL:126.1 | R16: . | X16: Дальнейшее развитие событий зависит от столь большого числа факторов
D17: ~~~~~~ | E17: 2.2 | F17: . | I17: II | L17: , | M17: с.36-48. | N17: = | O17: =CONCATENATE("↑",PL!A1,PL!D6,".",PL!E9) -> ↑PL:126.2 | R17: .
D18: ~~~~~~ | E18: 2.3 | F18: . | I18: III | L18: , | M18: с.49-75. | N18: = | O18: =CONCATENATE("↑",PL!A1,PL!D6,".",PL!E10) -> ↑PL:126.3 | R18: .
D19: ~~~~~~ | E19: 2.4 | F19: . | I19: IV | L19: , | M19: с.76-100. | N19: = | O19: =CONCATENATE("↑",PL!A1,PL!D6,".",PL!E11) -> ↑PL:126.4 | R19: .
D20: ~~~~~~ | E20: 2.5 | F20: . | I20: V | L20: , | M20: с.101-152. | N20: = | O20: =CONCATENATE("↑",PL!A1,PL!D6,".",PL!E12) -> ↑PL:126.5 | R20: .
D21: ~~~~~~ | E21: 2.6 | F21: . | I21: VI | L21: , | M21: с.153-177. | N21: = | O21: =CONCATENATE("↑",PL!A1,PL!D6,".",PL!E13) -> ↑PL:126.6 | R21: .
D22: ~~~~~~ | E22: 2.7 | F22: . | I22: VII | L22: , | M22: с.178-254. | N22: = | O22: =CONCATENATE("↑",PL!A1,PL!D6,".",PL!E14) -> ↑PL:126.7 | R22: .
D23: ~~~~~~ | E23: 2.8 | F23: . | I23: VIII | L23: , | M23: с.255-300. | N23: = | O23: =CONCATENATE("↑",PL!A1,PL!D6,".",PL!E15) -> ↑PL:126.8 | R23: .
D24: ~~~ | E24: 3 | F24: . | I24: Анекс. Часть I. Диалоги шестнадцать лет спустя
D25: ~~~~~~ | E25: 3.1 | F25: . | I25: Утраченные иллюзии, или от интеллектроники к информатике | L25: , | M25: с.303-340. | N25: = | O25: =CONCATENATE("↑",PL!A1,PL!D19,".",PL!E24) -> ↑PL:361.3.1 | R25: .
D26: ~~~~~~ | E26: 3.2 | F26: . | I26: Прикладная кибернетика: пример из области социологии | L26: , | M26: с.341-370. | N26: = | O26: =CONCATENATE("↑",PL!A1,PL!D19,".",PL!E25) -> ↑PL:361.3.2 | R26: .
D27: ~~~ | E27: 4 | F27: . | I27: Анекс. Часть II
D28: ~~~~~~ | E28: 4.1 | F28: . | I28: Этика технологии и технология этики | L28: , | M28: с.373-440. | N28: = | O28: =CONCATENATE("↑",PL!A1,PL!D19,".",PL!E27) -> ↑PL:361.4.1 | R28: .
D29: ~~~~~~ | E29: 4.2 | F29: . | I29: Биология и ценности | L29: , | M29: с.441-522. | N29: = | O29: =CONCATENATE("↑",PL!A1,PL!D19,".",PL!E28) -> ↑PL:361.4.2 | R29: .

Sheet DE
A1: DE: | C1: @ | D1: . | E1: numb | F1: . | G1: „“ ‚‘ | H1: , | I1: DE | J1: . – | K1: wydawca | L1: , | M1: rok, nr, S. | N1: = | O1: ↓↑ | P1: ; | Q1: ↓↑tłumaczenia | R1: .
B2: * | D2: ~~~~~~ | I2: Język Niemiecki; Deutsch; German (DE)
D3: (…)
C4: @ | D4: 176 | F4: . | G4: Lem S. | H4: , | I4: Dialoge / Autorisierte Übersetzung aus dem Polnischen von Jens Reuter | J4: . – | K4: F.a.M.: Suhrkamp Verlag | L4: , | M4: 1980, 319 S. | N4: = | Q4: =CONCATENATE("↓",D29,"; ",NL!A1,NL!D3) -> ↓207; NL:1 | R4: .
D5: ~~~ | I5: Inhalt:
D6: ~~~ | E6: 1 | F6: . | I6: I | L6: , | M6: S.9-33. | N6: = | O6: =CONCATENATE("↑",PL!A1,PL!D6,".",PL!E8) -> ↑PL:126.1 | P6: ; | Q6: =CONCATENATE("↓",D15,".",E17,", ",D20,".",E22,", ",D39,".",E41,", ",D43,".",E45,", ",D47,".",E49,", ") -> ↓190.2, 204.2, 291.2, 302.2, 316.2, | R6: .
D7: ~~~ | E7: 2 | F7: . | I7: II | L7: , | M7: S.34-46. | N7: = | O7: =CONCATENATE("↑",PL!A1,PL!D6,".",PL!E9) -> ↑PL:126.2 | P7: ; | Q7: =CONCATENATE("↓",D69,".",E70) -> ↓476.1 | R7: .
D8: ~~~ | E8: 3 | F8: . | I8: III | L8: , | M8: S.47-74. | N8: = | O8: =CONCATENATE("↑",PL!A1,PL!D6,".",PL!E10) -> ↑PL:126.3 | R8: .
D9: ~~~ | E9: 4 | F9: . | I9: IV | L9: , | M9: S.75-99. | N9: = | O9: =CONCATENATE("↑",PL!A1,PL!D6,".",PL!E11) -> ↑PL:126.4 | R9: .
D10: ~~~ | E10: 5 | F10: . | I10: V | L10: , | M10: S.100-153. | N10: = | O10: =CONCATENATE("↑",PL!A1,PL!D6,".",PL!E12) -> ↑PL:126.5 | R10: .
D11: ~~~ | E11: 6 | F11: . | I11: VI | L11: , | M11: S.154-178. | N11: = | O11: =CONCATENATE("↑",PL!A1,PL!D6,".",PL!E13) -> ↑PL:126.6 | R11: .
D12: ~~~ | E12: 7 | F12: . | I12: VII | L12: , | M12: S.179-257. | N12: = | O12: =CONCATENATE("↑",PL!A1,PL!D6,".",PL!E14) -> ↑PL:126.7 | R12: .
D13: ~~~ | E13: 8 | F13: . | I13: VIII | L13: , | M13: S.258-306. | N13: = | O13: =CONCATENATE("↑",PL!A1,PL!D6,".",PL!E15) -> ↑PL:126.8 | R13: .
B14: * | D14: ~~~ | E14: 9 | F14: . | I14: Nachwort / Aus dem Polnischen von Friedrich Griese | L14: , | M14: S.307-319. | N14: = | O14: =CONCATENATE("↑",My!A1,My!D2876,".",My!#REF!,"!") -> #REF! | P14: ; | Q14: =CONCATENATE("↓",RU!A1,RU!#REF!,".",RU!#REF!,", ",RU!#REF!,".",RU!#REF!,", ",RU!#REF!,".",RU!#REF!,"; ",#REF!,#REF!,".",#REF!,", ",#REF!,".",#REF!) -> #REF! | R14: .
C15: @ | D15: 190 | F15: . | G15: Lem S. | H15: , | I15: Die phantastischen Erzählungen / Hrsg. von Werner Berthel | J15: . – | K15: F.a.M.: Insel Verlag | L15: , | M15: 1980, 479 S. Im Inhalt:
E16: (…)
D17: ~~~ | E17: 2 | F17: . | I17: Die Auferstehungsmaschine / Aus dem Polnischen von Jens Reuter | L17: , | M17: S.343-361. | N17: = | O17: =CONCATENATE("↑",D4,".",E6,">") -> ↑176.1> | R17: .
E18: (…)
C20: @ | D20: 204 | F20: . | G20: Lem S. | H20: , | I20: Die phantastischen Erzählungen / Hrsg. von Werner Berthel | J20: . – | K20: F.a.M.: Insel Verlag | L20: , | M20: 1981, 479 S. 2. Auflage (51.-61. Tsd.). Im Inhalt:
E21: (…)
D22: ~~~ | E22: 2 | F22: . | I22: Die Auferstehungsmaschine / Aus dem Polnischen von Jens Reuter | L22: , | M22: S.343-361. | N22: = | O22: =CONCATENATE("↑",D4,".",E6,">") -> ↑176.1> | R22: .
E23: (…)
C24: @ | D24: 205 | F24: . | G24: Lem S. | H24: , | I24: Essays / Übersetzt von Friedrich Griese | J24: . – | K24: F.a.M.: Insel Verlag | L24: , | M24: 1981, 391 S. | N24: = | Q24: =CONCATENATE("↓",D68) -> ↓471a | R24: .
E25: (…)
D26: ~~~ | E26: 11 | F26: . | I26: Verlorene Illusionen oder Von der Intellektronik zur Informatik | L26: , | M26: S.247-283. | N26: = | O26: =CONCATENATE("↑",PL!A1,PL!D19,".",PL!E24) -> ↑PL:361.3.1 | P26: ; | Q26: =CONCATENATE("↓",D34,".",E36) -> ↓285.2 | R26: .
D27: ~~~ | E27: 12 | F27: . | I27: Biologie und Werte | L27: , | M27: S.284-361. | N27: = | O27: =CONCATENATE("↑",PL!A1,PL!D19,".",PL!E28) -> ↑PL:361.4.2 | P27: ; | Q27: =CONCATENATE("↓",D34,".",E37) -> ↓285.3 | R27: .
D28: ~~~ | E28: 13 | F28: . | I28: Angewandte Kybernetik: Ein Beispiel aus der Soziologie | L28: , | M28: S.362-391. | N28: = | O28: =CONCATENATE("↑",PL!A1,PL!D19,".",PL!E25) -> ↑PL:361.3.2 | P28: ; | Q28: =CONCATENATE("↓",D34,".",E38) -> ↓285.4 | R28: .
C29: @ | D29: 207 | F29: . | G29: Lem S. | H29: , | I29: Dialoge / Autorisierte Übersetzung aus dem Polnischen von Jens Reuter | J29: . – | K29: F.a.M.: Insel Verlag | L29: , | M29: 1981, 319 S. | N29: = | O29: =CONCATENATE("↑",D4) -> ↑176 | R29: .
C30: @ | D30: 281 | F30: . | G30: Jarzębski Jerzy | H30: , | I30: Zufall und Ordnung. Zum Werk Stanisław Lem / Aus dem Polnischen von Friedrich Griese | J30: . – | K30: F.a.M.: Suhrkamp Verlag | L30: , | M30: 1986, 219 S. Im Text des Buches:
E31: (…)
D32: ~~~ | E32: 2 | F32: . | G32: Lem S. | H32: , | I32: Ethik der Technologie und Technologie der Ethik | L32: , | M32: S.173. | N32: = | O32: =CONCATENATE("↑",PL!A1,PL!D17,"-") -> ↑PL:305- | R32: .
E33: (…)
C34: @ | D34: 285 | F34: . | G34: Lem S. | H34: , | I34: Über außersinnliche Wahrnehmung: Essays. Band 2 / Aus dem Polnischen von Friedrich Griese | J34: . – | K34: F.a.M.: Suhrkamp Verlag | L34: , | M34: 1987, 547 S. Inhalt:
E35: (…)
D36: ~~~ | E36: 2 | F36: . | I36: Verlorene Illusionen oder Von der Intellektronik zur Informatik | L36: , | M36: S.35-71. | N36: = | O36: =CONCATENATE("↑",D24,".",E26) -> ↑205.11 | R36: .
D37: ~~~ | E37: 3 | F37: . | I37: Biologie und Werte | L37: , | M37: S.72-149. | N37: = | O37: =CONCATENATE("↑",D24,".",E27) -> ↑205.12 | R37: .
D38: ~~~ | E38: 4 | F38: . | I38: Angewandte Kybernetik: ein Beispiel aus dem Bereich der Soziologie | L38: , | M38: S.150-179. | N38: = | O38: =CONCATENATE("↑",D24,".",E28) -> ↑205.13 | R38: .
C39: @ | D39: 291 | F39: . | G39: Lem S. | H39: , | I39: Die phantastischen Erzählungen / Hrsg. von Werner Berthel | J39: . – | K39: F.a.M.: Suhrkamp Verlag | L39: , | M39: 1988, 445 S. Im Inhalt:
E40: (…)
D41: ~~~ | E41: 2 | F41: . | I41: Die Auferstehungsmaschine / Aus dem Polnischen von Jens Reuter | L41: , | M41: S.343-361. | N41: = | O41: =CONCATENATE("↑",D4,".",E6,">") -> ↑176.1> | R41: .
...

Sheet EN
A1: EN: | C1: @ | D1: 188 | E1: numb | F1: . | G1: “” ‘’ | H1: , | I1: EN | J1: . – | K1: wydawca | L1: , | M1: rok, nr, s. □⌂¤ | N1: = | O1: ↓↑ | P1: ; | Q1: ↓↑tłumaczenia | R1: .
B2: * | D2: ~~~~~~ | I2: Język Angielski; English (EN)
D3: (…)
C4: @ | D4: 152a | F4: . | I4: Lem's Opinion / In: Stanisław Lem – The Official Site // The compiler: Wojciech Zemek | J4: . – | K4: Internet (Lem.pl) | L4: , | M4: 2005. Contains:
E5: (…)
D6: ~~~~~~ | E6: 24 | F6: . | I6: Dialogs | L6: , | M6: https://english.lem.pl/works/essays/dialogs/105-lems-opinion?showall=1 | N6: = | O6: =CONCATENATE("↑",My!A1,My!D16,".",My!E44,"<") -> ↑R11.25< | R6: .
D7: ~~~~~~ | E7: 25 | F7: . | I7: A look inside Dialogs: I / Translated from German by Frank Prengel | L7: , | M7: https://english.lem.pl/works/essays/dialogs/106-a-look-inside-dialogs | N7: = | O7: =CONCATENATE("↑",PL!A1,PL!D6,".",PL!E8,">") -> ↑PL:126.1> | R7: .
E8: (…)
C9: @ | D9: 158 | F9: . | G9: Keller Lech | H9: , | I9: Visions of the future in the writings of Stanisław Lem. Volume 1 – The Thesis | J9: . – | K9: Saarbrücken: Lambert Academic Publishing; OmniScriptum GmbH & Co. KG | L9: , | M9: 2010, 363 pp. The book includes fragments of articles and interviews translated into English for the first time:
E10: (…)
D11: ~~~ | E11: 6 | F11: . | G11: Lem S. | H11: , | I11: The Dialogues | L11: , | M11: pp.137-139,153. | N11: = | O11: =CONCATENATE("↑",PL!A1,PL!D6,"-") -> ↑PL:126- | R11: .
E12: (…)
C13: @ | D13: 171 | F13: . | G13: Swirski Peter | H13: , | I13: Stanislaw Lem – Philosopher of the Future | J13: . – | K13: Liverpool: Liverpool University Press | L13: , | M13: 2015, 203 pp. The book includes fragments of articles and interviews translated into English for the first time:
E14: (…)
D15: ~~~ | E15: 4 | F15: . | G15: Lem S. | H15: , | I15: Dialogues (full title of first edition) | L15: , | M15: pp.33-34. | N15: = | O15: =CONCATENATE("↑",PL!A1,PL!D6,"-") -> ↑PL:126- | R15: .
E16: (…)
C17: @ | D17: 172a | F17: . | G17: Majewski Paweł | H17: , | I17: Between an Animal and a Machine: Stanisław Lem’s Technological Utopia / Translated by Olga Kaczmarek | J17: . – | K17: Berlin: Peter Lang Verlag | L17: , | M17: 2018, 246 pp. Contains translation of fragments from essays by Stanisław Lem:
D18: ~~~ | E18: 1 | F18: . | G18: Lem S. | H18: , | I18: Dialogues (2nd edition) | L18: , | M18: pp.15,46-50,54-64. | N18: = | O18: =CONCATENATE("↑",PL!A1,PL!D19,"-") -> ↑PL:361- | R18: .
E19: (…)
D20: ~~~ | E20: 4 | F20: . | G20: Lem S. | H20: , | I20: Dialogues (full title of 1st edition) | L20: , | M20: p.39. | N20: = | O20: =CONCATENATE("↑",PL!A1,PL!D6,"-") -> ↑PL:126- | R20: .
E21: (…)
C22: @ | D22: 177 | F22: . | G22: Lem S. | H22: , | I22: Dialogues / Translated by Peter Butko | J22: . – | K22: Cambridge, London: The MIT Press | L22: , | M22: 2021, 358 pp. | N22: = | O22: =CONCATENATE("↑",PL!A1,PL!D19) -> ↑PL:361 | R22: .
D23: ~~~ | I23: Contents:
D24: ~~~ | E24: 1 | F24: . | I24: Preface to the Second Edition | L24: , | M24: pp.vii-ix.
D25: ~~~ | E25: 2 | F25: . | I25: Dialogues | L25: , | M25: pp.1-190.
D26: ~~~~~~ | E26: 2.1 | F26: . | I26: I | L26: , | M26: pp.3-20.
D27: ~~~~~~ | E27: 2.2 | F27: . | I27: II | L27: , | M27: pp.21-29.
D28: ~~~~~~ | E28: 2.3 | F28: . | I28: III | L28: , | M28: pp.31-46.
D29: ~~~~~~ | E29: 2.4 | F29: . | I29: IV | L29: , | M29: pp.47-62.
D30: ~~~~~~ | E30: 2.5 | F30: . | I30: V | L30: , | M30: pp.63-97.
D31: ~~~~~~ | E31: 2.6 | F31: . | I31: VI | L31: , | M31: pp.99-114.
D32: ~~~~~~ | E32: 2.7 | F32: . | I32: VII | L32: , | M32: pp.115-162.
D33: ~~~~~~ | E33: 2.8 | F33: . | I33: VIII | L33: , | M33: pp.163-190.
D34: ~~~ | E34: 3 | F34: . | I34: Supplement 1: The Dialogues Sixteen Years Later | L34: , | M34: pp.191-237.
D35: ~~~~~~ | E35: 3.1 | F35: . | I35: Lost Illusions, or From Intellectronics to Informatics | L35: , | M35: pp.193-217.
... D39: ~~~~~~ | E39: 4.2 | F39: . | I39: Biology and Values | L39: , | M39: pp.283-334.
D40: ~~~ | I40: Translator's Notes | L40: , | M40: pp.335-348.

Sheet SK
A1: SK: | C1: @ | D1: z | E1: numb | F1: . | G1: „…“ | H1: , | I1: SK | J1: . – | K1: wydawca | L1: , | M1: rok, nr, s. □⌂¤ | N1: = | O1: ↓↑ | P1: ; | Q1: ↓↑tłumaczenia | R1: . | S1: rodzaj
B2: * | D2: ~~~~~~ | I2: Język Słowacki; Slovenský jazyk; Slovak (SK)
D3: (…)
C4: @ | D4: 9 | F4: . | G4: Lem S. | H4: , | I4: Dialógy / Preložil: Peter Butko; Editor a jazyková redakcia: Pavel Matejovič | J4: . – | K4: Internet (Nun.sk) = Fórum pre vedu a umenie (Pezinok) | L4: , | M4: 2016, Elektronický prameň. http://www.nun.sk/Dialogy.htm
D5: ~~~ | E5: 1 | F5: . | I5: Predslov k druhému vydaniu | L5: . | N5: = | O5: =CONCATENATE("↑",PL!A1,PL!D19,".",PL!E21) -> ↑PL:361.1 | R5: .
D6: ~~~ | E6: 2 | F6: . | I6: Dialógy I-VII | L6: . | N6: = | O6: =CONCATENATE("↑",PL!A1,PL!D6,".",PL!E8,"÷",PL!E14) -> ↑PL:126.1÷7 | R6: .

Sheet CS
A1: CS: | B1: 1 | C1: @ | D1: . | E1: numb | F1: . | G1: „…“ | H1: , | I1: CS | J1: . – | K1: wydawca | L1: , | M1: rok, nr, s.□⌂¤ | N1: = | O1: =CONCATENATE("↑",) -> ↑ | P1: ; | Q1: =CONCATENATE("↓",,", ",) -> ↓, | R1: .
B2: * | D2: ~~~~~~ | I2: Język Czeski; Český jazyk; Czech (CS)
D3: (…)
C4: @ | D4: 22 | F4: . | G4: Weigel Pavel | H4: , | I4: Stanisław Lem: Životopis | J4: . – | K4: Praha: Magnet-Press | L4: , | M4: 1995, 112 s.⌂ V obsahu / Přeložil Pavel Weigel:
E5: (…)
D6: ~~~ | E6: 2 | F6: . | G6: Lem S. | H6: , | I6: Dialogy (název a názvy článků) | L6: , | M6: s.13,64-65. | N6: = | O6: =CONCATENATE("↑",PL!A1,PL!D6,"-") -> ↑PL:126- | R6: .
E7: (…)

Sheet RO
A1: RO: | C1: @ | D1: z | E1: numb | F1: . | G1: „…” | H1: , | I1: RO | J1: . – | K1: wydawca | L1: , | M1: rok, nr, s. □⌂¤ | N1: = | O1: ↓↑ | P1: ; | Q1: ↓↑tłumaczenia | R1: . | S1: rodzaj
B2: * | D2: ~~~~~~ | I2: Język Rumuński; Limba română; Romanian (RO)
D3: (…)
C4: @ | D4: 3 | F4: . | G4: Mitu Mihai | H4: , | I4: Un maestru al literaturii ştiinţifico-fantastice şi un mare umanist: Stanislaw Lem / În: Lem S., Ciberiada | J4: . – | K4: Bucureşti: Nemira | L4: , | M4: 1994, p.427-437. | N4: = | Q4: =CONCATENATE("↓",D8,", ",D9) -> ↓5, 7 | R4: .
D5: ~~~ | I5: În text:
D6: ~~~ | E6: 1 | F6: . | G6: Lem S. | H6: , | I6: Dialoguri (titlu 1 ed.) | L6: , | M6: p.432. | N6: = | O6: =CONCATENATE("↑",PL!A1,PL!D6,"-") -> ↑PL:126- | R6: .
E7: (…)
C8: @ | D8: 5 | F8: . | G8: Lem S. | H8: , | I8: Dialoguri (titlu 1 ed.); „O lume a basmului…“ (din interviul) / În: Mitu Mihai, Un maestru al literaturii ştiinţifico-fantastice şi un mare umanist: Stanislaw Lem // În: Mitu Mihai, Romano-Polonica: studii de istorie culturală | J8: . – | K8: Bucureşti: Editura Universităţii din Bucureşti | L8: , | M8: 2007, p.206,207. | N8: = | O8: =CONCATENATE("↑",D4) -> ↑3 | R8: .
C9: @ | D9: 7 | F9: . | G9: Lem S. | H9: , | I9: Dialoguri (titlu 1 ed.); „O lume a basmului…“ (din interviul) / În: Mitu Mihai, Un maestru al literaturii ştiinţifico-fantastice şi un mare umanist: Stanislaw Lem // În: Lem S., Ciberiada | J9: . – | K9: Bucureşti: Agora | L9: , | M9: 2013, p.290-291. | N9: = | O9: =CONCATENATE("↑",D4) -> ↑3 | R9: .

Sheet NL
A1: NL: | C1: @ | D1: z | E1: numb | F1: . | G1: “…” | H1: , | I1: FI | J1: . – | K1: wydawca | L1: , | M1: rok, nr, s. □⌂¤ | N1: = | O1: ↓↑ | P1: ; | Q1: ↓↑tłumaczenia | R1: . | S1: rodzaj
B2: * | D2: ~~~~~~ | I2: Język Niderlandzki; Nederlands; Dutch (NL)
B3: a+ | C3: @ | D3: 1 | F3: . | G3: Lem Stanislaw | H3: , | I3: Citaten uit ‘Dialogi’ / Teus de Jong, De schepping van Stanislaw Lem | J3: . – | K3: De Revisor (Amsterdam) | L3: , | M3: 1983, nr 5, p.31-42. | N3: = | O3: =CONCATENATE("↑",DE!A1,DE!D4,"-") -> ↑DE:176- | R3: .

Sheet BE
A1: BE: | C1: @ | D1: . | E1: numb | F1: . | G1: «» | H1: , | I1: BE | J1: . – | K1: wydawca | L1: , | M1: rok, nr, s. | N1: = | O1: ↓↑ | P1: ; | Q1: ↓↑tł | R1: . | S1: pierwodruk
B2: * | D2: ~~~~~~ | I2: Język Białoruski; Беларуская мова; Belarusian (BE)
D3: (…)
C4: @ | D4: 11 | F4: . | I4: Свет Станiслава Лема: цытаты, афарызмы / Укладальнiк Вiктар Язневiч; пераклад с польскай | J4: . – | K4: Мiнск: Галiяфы | L4: , | M4: 2022, 248 с. Змест:
E5: (…)
D6: ~~~~~~ | E6: 2.5 | F6: . | I6: Дыялогi / Dialogi | J6: / | K6: Пераклаў В. Язневiч | L6: , | M6: с.50-52. | N6: = | O6: =CONCATENATE("↑",[1]PL!A1,[1]PL!D742,"-") -> ↑PL:361- | R6: .
E7: (…)

Sheet MK
A1: MK: | C1: @ | D1: z | E1: numb | F1: . | G1: Lem | H1: , | I1: MK | J1: . – | K1: wydawca | L1: , | M1: rok, nr, s. □⌂¤ | N1: = | O1: ↓↑ | P1: ; | Q1: ↓↑tłumaczenia | R1: .
B2: * | D2: ~~~~~~ | I2: Język Macedoński; Македонски јазик; Macedonian (MK)
D3: (…)
C4: @ | D4: 3 | F4: . | I4: Светот на Станислав Лем [Цитати од Станислав Лем à la афоризми] / Одбрал и составил Виктор Jазневич; Превод: Милица Миркуловска | J4: . – | K4: Скопjе: Антолог | L4: , | M4: 2021, 288 с.
E5: (…)
D6: ~~~~~~ | E6: 2.5 | F6: . | I6: Дијалози (Dialogi) | L6: , | M6: с.54-56. | N6: = | O6: =CONCATENATE("↑",PL!A1,PL!D19,"-") -> ↑PL:361- | R6: .
E7: (…)

Sheet LO
A1: L | B1: PL: Po polsku | C1: @ | D1: . | E1: numb | F1: . | G1: „” | H1: / | I1: tytul | J1: . – | K1: wydawca | L1: , | M1: rok, nr, s. □⌂¤ | N1: = | O1: ↓↑ | P1: ; | Q1: ↓↑tłumaczenia | R1: . | V1: rodzaj | W1: k1 | X1: k2 | Y1: k3 | Z1: k4 | AA1: k5 | AB1: k6 | AC1: k7
G2: Część IV. Listy Otwarte i Apele, podpisane Stanisławem Lemem
C3: @ | D3: 1 | F3: . | G3: List do Zarządu Głównego Związku Literatów Polskich w obronie Pawła Jasienicy, Stefana Kisielewskiego i Januarego Grzędzińskiego | H3: / | I3: List na początek kwietnia 1968 r. podpisało ponad trzydziestu literatów, m. in.: Szczepański J.J. i Stanisław Lem. Publikacje o Liście:
D4: ~~~ | E4: 1 | F4: . | G4: Kwiek Julian | H4: , | I4: Marzec 1968 w Krakowie | J4: . – | K4: K.: Księgarnia Akademicka | L4: , | M4: 2008, s,232.
D5: ~~~ | E5: 2 | F5: . | G5: Rokicki Konrad | H5: , | I5: Literaci. Relacje między literatami a władzami PRL w latach 1956-1970 | J5: . – | K5: W.: Instytut Pamięci Narodowej | L5: , | M5: 2011, s.453.
D6: ~~~ | E6: 3 | F6: . | G6: Szczepański Jan Józef | H6: , | I6: Dziennik, tom III | J6: . – | K6: K.: Wydawnictwo Literackie | L6: , | M6: 2013, s.337-338.
B7: L1 + | C7: @ | D7: 2 | F7: . | G7: List o zmianie w Konstytucji – „List 23”. Nie opublikowany. Najprawdopodobniej nie wysłany do adresata. Podpisany 6-8 lutego 1976 r. Wsród podpisantów – Stanisław Lem. Tekst najprawdopodobniej taki sam jak w „Liście 101” poniżej:
D8: ~~~ | G8: Do Komisji Nadzwyczajnej Sejmu PRL dla przygotowania Ustawy o Zmianie Konstytucji Polskiej Rzeczypospolitej Ludowej (Warszawa, 31 stycznia 1976) [Memorial 101] | J8: . – | K8: Kultura (Paris) | L8: , | M8: 1976, nr 3, s.28-30.
C9: @ | D9: =D7+1 -> 3 | F9: . | G9: List w sprawie braci Jerzego i Ryszarda Kowalczyków [Do Przewodniczącego Rady Państwa PRL, obywatela Henryka Jabłońskiego, 13.05.1981]. Publikacje:
B10: L2 + | D10: ~~~ | E10: 1 | F10: . | G10: List w obronie braci Kowalczyków | H10: / | I10: Podpisali: Szczepański J.J., Szymborska W., Filipowicz K., Aleksandrowicz J., Lem St., Szacki J., Gieysstor K., Stanocz B., Szaniawski K., Zachnatowicz K., Olbrychski D., Dejmek K | J10: . – | K10: Agencja prasowa NSZZ Solidarność. Biuletyn pism związkowych i zakładowych (W.) | L10: , | M10: 1981, nr AS17 (19-20 V), s.305. | S10: 19-26.05.1981 | T10: 1981, 13.05 | U10: nr AS17 | V10: W sprawie braci Jerzego i Ryszarda Kowalczyków
B11: L2 + | D11: ~~~ | E11: 2 | F11: . | G11: List w obronie braci Kowalczyków | H11: / | I11: Podpisali: Te same jak wyżej | J11: . – | K11: Biuletyn informacyjny NSZZ Solidarność. Region Środkowo-Wschodni (Lublin) | L11: , | M11: 1981, nr 30 (1 VI), s.4.
B12: L2 + | D12: ~~~ | E12: 3 | F12: . | G12: List w obronie braci Kowalczyków | H12: / | I12: Podpisali: Te same jak wyżej | J12: . – | K12: Gdański Komitet Obrony Więzionych za Przekonania (Gdańsk) | L12: , | M12: 1981, nr 12 A (3 VI), s.1-2.
B13: L2 + | D13: ~~~ | E13: 4 | F13: . | G13: List w obronie braci Kowalczyków | H13: / | I13: Podpisali: Te same jak wyżej | J13: . – | K13: Informator NSZZ Solidarność Politechniki Śląskiej (Gliwice) | L13: , | M13: 1981, nr 29/41 (4 VI), s.7-8. | S13: od 04.VI.1981 r. | T13: 1981, 13.05 | U13: Internet, Keller - kopia z podpisami | V13: W sprawie braci Jerzego i Ryszarda Kowalczyków | W13: Przedruk z AS17
B14: L2 + | D14: ~~~ | E14: 5 | F14: . | G14: List w obronie braci Kowalczyków | H14: / | I14: Podpisali: Te same jak wyżej | J14: . – | K14: Biuletyn informacyjny NSZZ Solidarność Ziemi Puławskiej (Puławy) | L14: , | M14: 1981, nr 33/41 (10 VI), s.13-14. | S14: od 10 czerwca 1981 r. | T14: 1981, 13.05 | U14: Internet, Keller - kopia z podpisami | V14: W sprawie braci Jerzego i Ryszarda Kowalczyków | W14: Przedruk z AS17
B15: L2 + | D15: ~~~ | E15: 6 | F15: . | G15: List w obronie braci Kowalczyków | H15: / | I15: Podpisali: Te same jak wyżej / W: Keller Lech, Przyczynek do biografii Stanisława Lema // Acta Lemiana Monashiensis: Special Stanislas Lem Edition of Acta Polonica Monashiensis | J15: . – | K15: Acta Polonica Monashiensis (Melbourne, Australia) | L15: , | M15: 2020, vol.3, nr 2, p.190.
C16: @ | D16: =D9+1 -> 4 | F16: . | G16: List w obronę Jana Józefa Szczepańskiego. Publikacja:
B17: L | D17: ~~~ | G17: Ein offener Brief zur Verteidigung von Jan Józef Szczepański | H17: / | I17: Podpisali: Władysław Bartoszewski, Stanisław Lem | J17: . – | K17: Der Tagesspiegel (Berlin) | L17: , | M17: 1983, ?. | N17: = | O17: =CONCATENATE(DE!A1,DE!#REF!) -> #REF! | R17: .
C18: @ | D18: =D16+1 -> 5 | F18: . | G18: List o reaktywowaniu polskiej sekcji PEN-Clubu. Publikacja:
B19: L | D19: ~~~ | G19: Apel do przewodniczącego Rady Państwa gen. Wojciecha Jaruzelskiego i do marszałka Sejmu Romana Malinowskiego domagając się reaktywowania polskiej sekcji PEN-Clubu | H19: / | I19: List podpisali ponad 150 członków Pen Clubu. Wśród sygnatariuszy są m.in. Bronisław Geremek, Stefan Kisielewski, Stanisław Lem, Tadeusz Mazowiecki, Jan Józef Szczepański, Andrzej Kuśniewicz, Julian Stryjkowski, Władysław Terlecki | J19: . – | K19: Biuletyn PEN-Clubu (W.) | L19: , | M19: 1988, nr 25.05.1988. (http://www.encysol.pl/wiki/TL-1988/05) | S19: http://www.encysol.pl/wiki/TL-1988/05
C20: @ | D20: =D18+1 -> 6 | F20: . | G20: List o wolnych wyborach [Oświadczenie o prawie każdego obywatela, zgłoszonego przez wspierający go elektorat, do kandydowania w wyborach do Sejmu]. Publikacje:
B21: L + | D21: ~~~ | E21: 1 | F21: . | G21: O wolne wybory | H21: / | I21: Podpisali 100 sygnatariuszy, przedstawicieli świata nauki i kultury (Gdańsk, Gliwice, Kraków, Lublin, Łódź, Poznań, Wrocław, Warszawa), m.in.: G. Białkowski, J. Bocheński, E. Bryll, A. Drawicz, Cz. Hernas, M. Iłowiecki, M. Janion, T. Konwicki, S. Lem, J.J. Lipski, A. Łapicki, J. Maziarski, A. Międzyrzecki, B. Skarga, J. Sławiński, J.J. Szczepański, A. Szczepkowski, A. Szczypiorski, J. Turowicz, A. Wajda, K. Zachwatowicz, J. Żuławski | J21: . – | K21: KOS, Komitet Oporu Społecznego (W.) | L21: , | M21: 1989, nr 2, s.2. | S21: – O wolne wybory… KOS 1989 nr 2(152): 15 I s. 2 [oświadczenie o prawie każdego obywatela, zgłoszonego przez wspierający go elektorat, do kandydowania w wyborach do Sejmu; dat.: Gd., Gliwice, Kr., Lubl., Łódź, Pozn., Wr., Wwa, jesień 1988; podp. 100 sygnatariuszy, przedstawicieli świata nauki i kultury, m.in.: G. Białkowski, J. Bocheński, E. Bryll, A. Drawicz, Cz. Hernas, M. Iłowiecki, M. Janion, T. Konwicki, S. Lem, J.J. Lipski, A. Łapicki, J. Maziarski, A. Międzyrzecki, B. Skarga, J. Sławiński, J.J. Szczepański, A. Szczepkowski, A. Szczypiorski, J. Turowicz, A. Wajda, K. Zachwatowicz, J. Żuławski; oświadczenie przekazano 30 XII 1988 na ręce Rzecznika Praw Obywatelskich i pozostaje ono otwarte do podpisu dla zainteresowanych osób]; [not. inf.:] Sejm dla każdego. Tyg. Maz. Solid. 1989 nr 276: 4 I s. 3
B22: L + | D22: ~~~ | E22: 2 | F22: . | G22: Sejm dla każdego | H22: / | I22: Podpisali: Tischner Józef, Turowicz Jerzy, Findeisen Władysław, Gieysztor Aleksander, Kielanowski Jan, Bryll Ernest, Lem Stanisław, Szczypiorski Andrzej, Lutosławski Witold, Łapicki Andrzej, Szczepkowski Andrzej, Wajda Andrzej, Bujak Adam, Mleczko Andrzej, Zawada Andrzej, Remuszko Stanisław i inni | J22: . – | K22: Tygodnik Mazowsze Solidarność (W.) | L22: , | M22: 1989 nr 276 (4 I), s.3. | T22: Gajewska-s.577. | U22: [12] O wolne wybory, „KOS” [Komitet Oporu Społecznego „Solidarność”], nr 2 (152) z 15 stycznia 1989, s. 2. Dziękuję Michałowi Paziewskiemu za zwrócenie mi uwagi na ten dokument.
C23: @ | D23: =D20+1 -> 7 | F23: . | G23: List-protest przeciw masakrze w Chinach [Apel solidarnościowy popierający dążenia demokratyczne narodu chińskiego, wzywający rządy świata i międzynarodową opinię publiczną do podjęcia działań skłaniających władze ChRL do zaprzestania masakry ludności]. Publikacje:
B24: L + | D24: ~~~ | E24: 1 | F24: . | G24: Zaprzestać masakry! | H24: / | I24: Podpisali: Białkowski Grzegorz; Bober Andrzej; Bocheński Jacek; Bogusławski Stefan; Ciesielski Roman; Czabański Krzysztof; Drawicz Andrzej; Findeisen Władysław; Geremek Bronisław; Hall Aleksander; Hartwig Julia; Hniedziewicz Przemysław; Koj Aleksander; Konwicki Tadeusz; Kozłowski Krzysztof; Krawczyk Radał; Kunicki-Goldfinger Władysław; Lem Stanisław; Lipski Jan Józef; Lutosławski Witold; Mazowiecki Tadeusz; Michnik Adam; Międzyrzecki Artur; Olszewski Jan; Radziwiłł Konstanty; Remuszko Stanisław; Ryszkiewicz Marcin; Siła-Nowicki Władysław; Skalski Ernest; Starczewska Krystyna; Starzyński Wojciech; Surdykowski Jerzy; Szczepański Jan Józef; Szumowski Maciej; Tischner Józef; Wajda Andrzej; Zachwatowicz Krystyna; Zbrożyna Barbara; Ziółkowski Janusz; Żuławski Juliusz | J24: . – | K24: Gazeta Wyborcza (W.) | L24: , | M24: 1989, nr 22 (07.06.1989), s.2. | T24: [Protest p-ciw masakrze w Chiny podpisali: Białkowski Grzegorz; Bober Andrzej; Bocheński Jacek; Bogusławski Stefan; Ciesielski Roman; Czabański Krzysztof; Drawicz Andrzej; Findeisen Władysław; Geremek Bronisław; Hall Aleksander; Hartwig Julia; Hniedziewicz Przemysław; Koj Aleksander; Konwicki Tadeusz; Kozłowski Krzysztof; Krawczyk Radał; Kunicki-Goldfinger Władysław; Lem Stanisław; Lipski Jan Józef; Lutosławski Witold; Mazowiecki Tadeusz; Michnik Adam; Międzyrzecki Artur; Olszewski Jan; Radziwiłł Konstanty; Remuszko Stanisław; Ryszkiewicz Marcin; Siła-Nowicki Władysław; Skalski Ernest; Starczewska Krystyna; Starzyński Wojciech; Surdykowski Jerzy; Szczepański Jan Józef; Szumowski Maciej; Tischner Józef; Wajda Andrzej; Zachwatowicz Krystyna; Zbrożyna Barbara; Ziółkowski Janusz; Żuławski Juliusz] | U24: OCR nr 0 dodatek do OCR, dodatek do Gazety Wyborczej nr 21, wydanie z dnia 06/06/1989, str. 2 | V24: Gazeta Wyborcza nr 22, wydanie z dnia 07/06/1989, str. 2 | AA24: WJ_21
B25: Lx + | D25: ~~~ | E25: 2 | F25: . | G25: Zaprzestać masakry! | H25: / | I25: Podpisali m.in.: G. Białkowski, J. Bocheński, A. Drawicz, J. Hartwig, T. Konwicki, S. Lem, J.J. Lipski, A. Michnik, T. Mazowiecki, A. Międzyrzecki, J. Surdykowski, J.J. Szczepański, A. Wajda, K. Zachwatowicz, J. Żuławski | J25: . – | K25: KOS, Komitet Oporu Społecznego (W.) | L25: , | M25: 1989, nr 12 (11 VI), s.1. | S25: 1989: Zaprzestać masakry! KOS 1989 nr 12(162): 11 VI s. 1 [apel solidarnościowy popierający dążenia demokratyczne nar. chińskiego, wzywający rządy świata i międzynar. opinię publiczną do podjęcia działań skłaniających władze ChRL do zaprzestania masakry ludności; podp. m.in.: G. Białkowski, J. Bocheński, A. Drawicz, J. Hartwig, T. Konwicki, S. Lem, J.J. Lipski, A. Michnik, T. Mazowiecki, A. Międzyrzecki, J. Surdykowski, J.J. Szczepański, A. Wajda, K. Zachwatowicz, J. Żuławski]. | T25: Gajewska-s.579. | U25: [18] Zaprzestać masakry!, „KOS” z 11 czerwca 1989, s. 1. Dziękuję Michałowi Paziewskiemu za zwrócenie mi uwagi na ten artykuł.
D26: (…)

Sheet My
A1: R | B1: PL: Po polsku | C1: @ | D1: . | E1: numb | F1: . | G1: „” | H1: , | I1: tytul | J1: . – | K1: wydawca | L1: , | M1: rok, nr, s. □⌂¤ | N1: = | O1: ↓↑ | P1: ; | Q1: ↓↑tłumaczenia | R1: . | S1: rodzaj | T1: k1 | U1: k2 | V1: k3 | W1: k4 | X1: k5 | Y1: k6 | Z1: k7
D2: ~~~~~~ | G2: Część III. Rękopisy
C3: @ | D3: 1 | F3: . | G3: Lem S. | H3: , | I3: Ogólna teoria funkcji mózgu | J3: . – | K3: Maszynopis | L3: , | M3: 1940-1945. W prywatnym Archiwum Stanisława Lema. | S3: esej naukowy | T3: mózg | AA3: Lem S.
C4: @ | D4: =D3+1 -> 2 | F4: . | G4: Lem S. | H4: , | I4: REFERAT w sprawie ulepszeń technicznych, oraz nowych konstrukcji na polu przemysłu zbrojeniowego | J4: . – | K4: Maszynopis | L4: , | M4: 1944 (17.10). Centralny Archiwum Ministerstwa Obrony Rosyjskiej Federacji, fundusz 38, spis 11350, sprawa 1039 (ЦАМО РФ, фонд 38, опись 11350, дело 1039). | R4: . | S4: referat | AA4: Lem S.
C5: @ | D5: =D4+1 -> 3 | F5: . | G5: Lem S. | H5: , | I5: Historia jednego pomysłu [Dzieje pewnego pomysłu] | J5: . – | K5: Maszynopis | L5: , | M5: 1978. W prywatnym Archiwum Stanisława Lema. | R5: . | AA5: Lem S.
C6: @ | D6: =D5+1 -> 4 | F6: . | G6: Lem S. | H6: , | I6: Baśniowy świat „Cyberiady” Stanisława Lema | J6: . – | K6: Maszynopis | L6: , | M6: 1985. W prywatnym Archiwum Stanisława Lema | S6: s.229-230 książki Tomasza Lema | AA6: Lem S.
C7: @ | D7: =D6+1 -> 5 | F7: . | G7: P.Znawca [Lem S.] | H7: , | I7: Rozdroże | J7: . – | K7: Maszynopis | L7: , | M7: 1988. Warszawa (Paris): Biblioteka Narodowa / Archiwum IL Kultura / ILK MO 1988/0127 / 19 k. / Lista nr 1 z 1988 r. / W: Materiały odrzucone. | R7: . | AA7: P.Znawca [Lem S.]
C8: @ | D8: 5a | F8: . | G8: Lem S. | H8: , | I8: Wspomnienia podyktowane żonie | J8: . – | K8: Maszynopis | L8: , | M8: 1990. W prywatnym Archiwum Stanisława Lema | R8: .
C9: @ | D9: 5b | F9: . | G9: Lem S. | H9: , | I9: Oświadczenie z 28.11.1990 (z Aneksem z 7.12.1990 oraz dodatkiem do Aneksu) | J9: . – | K9: Maszynopis | L9: , | M9: 1990. W prywatnym Archiwum Stanisława Lema | R9: .
C10: @ | D10: 5c | F10: . | G10: Lem S. | H10: , | I10: Różne dokumenty | J10: . – | K10: Maszynopis | L10: , | M10: 1990. W prywatnym Archiwum Stanisława Lema | R10: .
C11: @ | D11: =D7+1 -> 6 | F11: . | I11: Lem 1991. Wywiad ze Stanisławem Lemem / Przeprowadziła Elżbieta Binswanger-Stefańska | J11: . – | K11: Maszynopis | L11: , | M11: 1991. Warszawa (Paris): Biblioteka Narodowa / Archiwum IL Kultura / ILK MO 1992.2/0048 / 10 k. / Lista nr 2 z 1992 r. / W: Materiały odrzucone. | R11: . | AA11: Binswanger-Stefańska Elżbieta
C12: @ | D12: =D11+1 -> 7 | F12: . | G12: Lem S. | H12: , | I12: Listy do Redakcji [Kultury Paryskiej] od Stanisława Lema / 16 listów do Redakcji; Kraków, Wiedeń: 1957, 1983-1984, 1986-1988, 1992, 1997, 2000. Niektóre z listów z lat 1983-1988 podpisane pseudonimem P.Znawca | J12: . – | K12: Maszynopis | L12: , | M12: 2000. Warszawa (Paris): Biblioteka Narodowa / Archiwum IL Kultura / ILK KOR RED Lem / 36 k. / W: Korespondencja Redakcji – teka 412; Korespondencja Krajowa; Korespondencja Poufna. | AA12: Lem S.
C13: @ | D13: =D12+1 -> 8 | F13: . | G13: Lem S. | H13: , | I13: Aide mémoire – List w sprawach zawodowych skierowany do Ministerstwa Kultury i Sztuki, 18.10.1978. I inne dokumenty | J13: . – | K13: Maszynopis | L13: , | M13: 2000. Warszawa: Archiwum Akt Nowych / AAN, PZPR, Komitet centralny w Warszawie. Wydział Kultury, sygn. LVI-1192. | S13: https://www.aan.gov.pl/lem/?fbclid=IwAR12pMkgSzrmufmbW5DFtldxKHS4h7e0PHp0PPqSsZRxbzcBZ4txWvPjLSo#page/16
C14: @ | D14: =D13+1 -> 9 | F14: . | G14: Hussarski R., Lem S. | H14: , | I14: „Jacht Paradise” (60 s.) | J14: . – | K14: Maszynopis | L14: , | M14: 2000. Archiwum Państwowe w Kielcach. Państwowy Teatr im. Stefana Żeromskiego w Kielcach. Scenariusze sztuk niegranych. Sygn.21/365/0/-/552. | S14: https://szukajwarchiwach.pl/21/365/0/-/552?q=lem&wynik=15&rpp=15&page=1#tabJednostka
C15: @ | D15: =D14+1 -> 10 | F15: . | G15: Lem S. | H15: , | I15: Utwory niedrukowane : wiersze: „Miłość”, „Owady”, „Prezentacja” (12 s.) | J15: . – | K15: Maszynopis | L15: , | M15: 2000. Archiwum Narodowe w Krakowie. Redakcja miesięcznika "Twórczość" w Krakowie. Series [3], Units [375], Sygn.29/821/0/2/135. | S15: https://szukajwarchiwach.pl/29/821/0/2/135?q=Stanisław+Lem&wynik=13&rpp=15&page=1#tabJednostka
C16: @ | D16: =D15+1 -> 11 | F16: . | G16: Lem S. | H16: , | I16: Komentarz autora / W: Serwis poświęcony twórczości Stanisława Lema // Ułożył Wojciech Zemek | J16: . – | K16: Internet (Lem.pl) | L16: , | M16: 2005-2013, www.lem.pl . Zawiera (12.06.2020):
D17: ~~~ | I17: Beletrystyka | L17: , | M17: https://solaris.lem.pl/ksiazki/beletrystyka
D18: ~~~~~~ | E18: 1 | F18: . | I18: Astronauci | R18: . | S18: https://solaris.lem.pl/ksiazki/beletrystyka/astronauci/53-komentarz-astronauci
D19: ~~~~~~ | E19: 2 | F19: . | I19: Cyberiada | R19: . | S19: https://solaris.lem.pl/ksiazki/beletrystyka/cyberiada/59-komentarz-cyberiada
D20: ~~~~~~ | E20: 3 | F20: . | I20: Człowiek z Marsa | R20: . | S20: https://solaris.lem.pl/ksiazki/beletrystyka/czlowiek-z-marsa/62-komentarz-czlowiek-z-marsa
D21: ~~~~~~ | E21: 4 | F21: . | I21: Dzienniki gwiazdowe | S21: https://solaris.lem.pl/ksiazki/beletrystyka/dzienniki-gwiazdowe/65-komentarz-dzienniki-gwiazdowe
D22: ~~~~~~ | E22: 5 | F22: . | I22: Eden | R22: . | S22: https://solaris.lem.pl/ksiazki/beletrystyka/eden
D23: ~~~~~~ | E23: 6 | F23: . | I23: Fiasko | R23: . | S23: https://solaris.lem.pl/ksiazki/beletrystyka/fiasko/71-komentarz-fiasko
D24: ~~~~~~ | E24: 7 | F24: . | I24: Głos Pana | R24: . | S24: https://solaris.lem.pl/ksiazki/beletrystyka/glos-pana/80-komentarz-glos
D25: ~~~~~~ | E25: 8 | F25: . | I25: Katar | R25: . | S25: https://solaris.lem.pl/ksiazki/beletrystyka/katar/85-komentarz-katar
D26: ~~~~~~ | E26: 9 | F26: . | I26: Kongres futurologiczny | R26: . | S26: https://solaris.lem.pl/ksiazki/beletrystyka/kongres-futurologiczny/91-komentarz-kongres-futurologiczny
D27: ~~~~~~ | E27: 10 | F27: . | I27: Niezwyciężony | R27: . | S27: https://solaris.lem.pl/ksiazki/beletrystyka/niezwyciezony
D28: ~~~~~~ | E28: 11 | F28: . | I28: Obłok Magellana | R28: . | S28: https://solaris.lem.pl/ksiazki/beletrystyka/oblok-magellana
D29: ~~~~~~ | E29: 12 | F29: . | I29: Opowieści o pilocie Pirxie | R29: . | S29: https://solaris.lem.pl/ksiazki/beletrystyka/pirx
D30: ~~~~~~ | E30: 13 | F30: . | I30: Pamiętnik znaleziony w wannie | R30: . | S30: https://solaris.lem.pl/ksiazki/beletrystyka/pamietnik/100-komentarz-pamietnik-znaleziony-w-wannie
D31: ~~~~~~ | E31: 14 | F31: . | I31: Pokój na Ziemi | R31: . | S31: https://solaris.lem.pl/ksiazki/beletrystyka/pokoj-na-ziemi/115-komentarz-pokoj-na-ziemi
D32: ~~~~~~ | E32: 15 | F32: . | I32: Powrót z gwiazd | R32: . | S32: https://solaris.lem.pl/ksiazki/beletrystyka/powrot-z-gwiazd
D33: ~~~~~~ | E33: 16 | F33: . | I33: Przekładaniec | R33: . | S33: https://solaris.lem.pl/ksiazki/beletrystyka/przekladaniec
... D39: ~~~~~~ | E39: 22 | F39: . | I39: Zagadka | R39: . | S39: https://solaris.lem.pl/ksiazki/beletrystyka/zagadka
D40: ~~~ | I40: Apokryfy | L40: , | M40: https://solaris.lem.pl/ksiazki/apokryfy
D41: ~~~~~~ | E41: 23 | F41: . | I41: Biblioteka XXI wieku | R41: . | S41: https://solaris.lem.pl/ksiazki/apokryfy/biblioteka21wieku/151-komentarz-apokryfy
D42: ~~~~~~ | E42: 24 | F42: . | I42: Golem XIV | R42: . | S42: https://solaris.lem.pl/ksiazki/apokryfy/golem14/155-komentarz-golem14
D43: ~~~ | I43: Eseje | L43: , | M43: https://solaris.lem.pl/ksiazki/eseje
D44: ~~~~~~ | E44: 25 | F44: . | I44: Dialogi | R44: . | S44: https://solaris.lem.pl/ksiazki/eseje/dialogi/159-komentarz-dialogi
D45: ~~~~~~ | E45: 26 | F45: . | I45: Fantastyka i futurologia | R45: . | S45: https://solaris.lem.pl/ksiazki/eseje/fantastyka-i-futurologia/163-komentarz-fantastyka-i-futurologia
...

Sheet About
A1: A | B1: N | C1: «A» „R” | D1: . | E1: Książki, specjalne wydania czasopismów i najwazniejsze artykuły o Stanisławie Lemie (chronologicznie) / Ułożył Wiktor Jaźniewicz | F1: = | G1: ↓↑ | H1: .
A2: @ | B2: 1 | D2: . | E2: Kijowski Andrzej, Fantazja i realizm. –
C3: 1 | D3: ) | E3: Życie Literackie (K.), 1952, nr 12, s.11;
C4: 2 | D4: ) | E4: W: Kijowski A., Różowe i czarne. – K.: Wydawnictwo Literackie, 1957.
A5: @ | B5: 2 | D5: . | E5: Starowieyska-Morstinowa Zofia, W kosmicznej próżni. – Tygodnik Powszechny (K.), 1952, nr 22, s.7.
A6: @ | B6: 3 | D6: . | E6: Białoborski Eustachy, Powieść fantastyczno-naukowa? [O powieści „Astronauci” S. Lema]. – Problemy (W.), 1953, nr 7, s.502-503.
A7: @ | B7: 4 | D7: . | E7: Terlecki Olgierd, O pisarstwie Stanisława Lema – felieton dyskusyjny. – Dziennik Polski (K.), 1954, nr 213, s.3-4.
A8: @ | B8: 5 | D8: . | E8: Flaszen Ludwik, Czas rzeczywiście nieutracony. – Życie Literackie (K.), 1955, nr 50, s.7,11.
A9: @ | B9: 6 | D9: . | E9: Włodek Adam, Lem gwiazdowy. – Dziennik Polski (K.), 1957, nr 108, s. 3-4.
A10: @ | B10: 7 | D10: . | E10: Maciąg Włodzimierz, Literatura Lema. – Życie Literackie (K.), 1959, nr 15, s.2.
A11: @ | B11: 8 | D11: . | E11: Maciąg Włodzimierz, Słownik polskich pisarzy współczesnych: Stanisław Lem. – Tygodnik kulturalny (W.), 1963, nr 46, s.6.
A12: @ | B12: 9 | D12: . | E12: Kołakowski Leszek, Informacja i utopia. –
C13: 1 | D13: ) | E13: Twórczość (W.), 1964, nr 11, s.115-123;
C14: 2 | D14: ) | E14: W: Kołakowski L., Pochwała niekonsekwencji. Pisma rozproszone z lat 1955-1968, Tom 3. – L.: Oficyna Wydawnicza Nowa, 1989.
A15: @ | B15: 10 | D15: . | E15: Summa Technologiae. Dyskusja nad książką Stanisława Lema. – Studia Filozoficzne (W.), 1965, nr 2, s.95-135; nr 3, s.3-37. | H15: .
B16: ~~~ | E16: W dyskusji udział wzięli: Stanisław Lem, Józef Hurwic, Wacław Mejbaum, Helena Eilstein, Andrzej Bednarczyk i Władysław Krajewski.
A17: @ | B17: 11 | D17: . | E17: Kijowski Andrzej, Stanisław Lem czyli humanista w Kosmosie. –
C18: 1 | D18: ) | E18: Radar (W.), 1966, nr 8, s.8-9;
C19: 2 | D19: ) | E19: W: Kijowski A., Dzieje literatury pozbawionej sankcji. Vol. 2. – K.: Instytut Literatury, 2020, s.139-147.
A20: @ | B20: 12 | C20: . 1 | D20: . | E20: Андреев Кирилл, Четыре будущих Станислава Лема / В кн.:
C21: 1 | D21: ) | E21: Лем С., Магелланово облако. – М.: Детская литература, 1966, с.5-20;
C22: 2 | D22: ) | E22: Лем С., Высокий замок. – М.: Молодая гвардия, 1969, с.132-142. | F22: = | G22: #REF! | H22: .
B23: ~~~ | E23: Wydania w innych językach:
B24: ~~~ | C24: 2 | D24: . | E24: Andreev Kirill, The Four Futures of Stanislaw Lem / Translated by John W. Andrews. –
C25: 1 | D25: ) | E25: Moebius Trip (Peoria, Illinois), 1972, nr 12 (March), p.4-15;
C26: 2 | D26: ) | E26: Renaissance (Berkeley Heights, N.J.), 1972, vol.4, nr 1; nr 2, p.8-13. | H26: .
B27: ~~~ | C27: 3 | D27: . | E27: Andrejew Kirill, Die vier Zukunften Stanislaw Lems / Aus dem Russischen von Beate Sorger. – Quarber Merkur (Wien), 1975, Nr 41, S.18-26. | H27: .
A28: @ | B28: 13 | C28: . 1 | D28: . | E28: Pośpieszalska Nelly [Eilstein Helena], „Głos Pana”, czyli Zwierciadło z Nieba. – Nurt (Poznań), 1969, nr 7, s.34-39; nr 8, s.33-38. Wydanie w innym języku:
B29: ~~~ | C29: 2 | D29: . | E29: Pośpieszalska Nelly, Zu »Glos Pana« (Die Stimme des Herrn) von Stanislaw Lem / Aus dem Polnischen übertragen, ausgewählt und komentiert von Irmtraud Zimmermann-Göllheim. –
C30: 1 | D30: ) | E30: Quarber Merkur (Wien), 1970, Nr 24, S.29-52;
C31: 2 | D31: ) | E31: In: Stanislaw Lem. Der dialektische Weise aus Kraków – F.a.M.: Insel Verlag, 1976, S.91-134. | F31: = | G31: ↓A24 | H31: .
A32: @ | B32: 14 | C32: . 1 | D32: . | E32: Suvin Darko, The Open-Ended Parables of Stanislaw Lem and “Solaris” / In: Lem S., Solaris. –
C33: 1 | D33: ) | E33: N.Y.: Walker & Co., 1970, p.206-216;
C34: 2 | D34: ) | E34: N.Y.: Berkley Medallion, 1971, p.212-223;
C35: 3 | D35: ) | E35: L.: The Science Fiction Book Club, 1973, p.206-216;
C36: 4 | D36: ) | E36: N.Y.: Berkley Publishing, 1978, p.212-223;
C37: 5 | D37: ) | E37: N.Y.: Berkley Publishing, 1982, p.212-223. | H37: .
B38: ~~~ | E38: Wydania w innych językach:
B39: ~~~ | C39: 2 | D39: . | E39: Suvin Darko, Stanislaw Lems Parabel »Solaris«. – Quarber Merkur (Wien), 1971, Nr 25, S.64-67. | H39: .
B40: ~~~ | C40: 3 | D40: . | E40: Suvin Darko, As parábolas sem conclusões de Stanislaw Lem e «Solaris» / Tradução Inês Busse // No: Lem S., Solaris. –
...

Sheet PLF
A1: F | B1: PL: Po polsku | C1: @ | D1: . | E1: numb | F1: . | G1: „” | H1: , | I1: tytul | J1: . – | K1: wydawca | L1: , | M1: rok, nr, s. □⌂¤ | N1: = | O1: ↓↑ | P1: ; | Q1: ↓↑tłumaczenia | R1: . | S1: rodzaj
D2: ~~~~~~ | G2: 1. Pierwszy zbiór pism Stanisława Lema post mortem –
D3: ~~~~~~ | G3: Biblioteka Gazety Wyborczej. Dzieła, Tomy I-XXXIII
B4: * | C4: @ | D4: 1 | F4: . | G4: Lem S. | H4: , | I4: Dzienniki gwiazdowe. Dzieła, T.I / Rysunek na okładce: Lem S., Nocnik innoplanetarny. – W.: Agora SA, 2008, 384 s. | M4: □
D5: ~~~ | I5: Spis treści:
D6: ~~~ | E6: 1 | F6: . | I6: Przedmowa | L6: , | M6: s.5-6.
D7: ~~~ | E7: 2 | F7: . | I7: Wstęp | L7: , | M7: s.7-8.
D8: ~~~ | I8: Z dzienników gwiazdowych Ijona Tichego
D9: ~~~~~~ | E9: 3 | F9: . | I9: Podróż siódma | L9: , | M9: s.13-28.
D10: ~~~~~~ | E10: 4 | F10: . | I10: Podróż ósma | L10: , | M10: s.29-45.
D11: ~~~~~~ | E11: 5 | F11: . | I11: Podróż jedenasta | L11: , | M11: s.47-76.
D12: ~~~~~~ | E12: 6 | F12: . | I12: Podróż dwunasta | L12: , | M12: s.77-85.
D13: ~~~~~~ | E13: 7 | F13: . | I13: Podróż trzynasta | L13: , | M13: s.87-104.
D14: ~~~~~~ | E14: 8 | F14: . | I14: Podróż czternasta | L14: , | M14: s.105-125.
D15: ~~~~~~ | E15: 9 | F15: . | I15: Podróż osiemnasta | L15: , | M15: s.127-137.
D16: ~~~~~~ | E16: 10 | F16: . | I16: Podróż dwudziesta | L16: , | M16: s.139-174.
D17: ~~~~~~ | E17: 11 | F17: . | I17: Podróż dwudziesta pierwsza | L17: , | M17: s.175-225.
D18: ~~~~~~ | E18: 12 | F18: . | I18: Podróż dwudziesta druga | L18: , | M18: s.227-239.
D19: ~~~~~~ | E19: 13 | F19: . | I19: Podróż dwudziesta trzecia | L19: , | M19: s.241-246.
D20: ~~~~~~ | E20: 14 | F20: . | I20: Podróż dwudziesta czwarta | L20: , | M20: s.247-258.
... D22: ~~~~~~ | E22: 16 | F22: . | I22: Podróż dwudziesta ósma | L22: , | M22: s.273-289.
D23: ~~~ | I23: Ze wspomnień Ijona Tichego
D24: ~~~~~~ | E24: 17 | F24: . | I24: Ze wspomnień Ijona Tichego. I | L24: , | M24: s.293-305.
D25: ~~~~~~ | E25: 18 | F25: . | I25: Ze wspomnień Ijona Tichego. II | L25: , | M25: s.307-318.
D26: ~~~~~~ | E26: 19 | F26: . | I26: Ze wspomnień Ijona Tichego. III | L26: , | M26: s.319-327.
D27: ~~~~~~ | E27: 20 | F27: . | I27: Ze wspomnień Ijona Tichego. IV | L27: , | M27: s.329-339.
D28: ~~~~~~ | E28: 21 | F28: . | I28: Ze wspomnień Ijona Tichego. V (Tragedia pralnicza) | L28: , | M28: s.341-357.
D29: ~~~ | I29: Posłowie: Jarzębski Jerzy, Spór między Münchhausenem a Guliwerem | L29: , | M29: s.359-364.
D30: ~~~ | I30: Orliński Wojciech, Słownik terminów Lemowskich, Cz.I | L30: , | M30: s.367-372.
D31: ~~~ | I31: Orliński Wojciech, Lema nie ma? | L31: , | M31: s.373-378.
D32: ~~~ | I32: Nota wydawnicza | L32: , | M32: s.379.
D33: (…)
B34: * | C34: @ | D34: 33 | F34: . | G34: Lem S. | H34: , | I34: Przekładaniec. Dzieła, T.XXXIII / Rys. na okł.: Lem S., Czajak połkliwy nocą z łupem (na górze), Trojanka z dzieckiem. – W.: Agora SA, 2010, 312 s. | M34: □
D35: ~~~ | I35: Spis treści:
B36: - | D36: ~~~ | E36: 1 | F36: . | I36: Czy pan istnieje, Mr. Johns? | L36: , | M36: s.5-12.
B37: - | D37: ~~~ | E37: 2 | F37: . | I37: Wierny robot: Widowisko telewizyjne | L37: , | M37: s.13-35.
B38: - | D38: ~~~ | E38: 3 | F38: . | I38: Wyprawa profesora Tarantogi: Widowisko w sześciu częściach | L38: , | M38: s.37-82.
B39: - | D39: ~~~ | E39: 4 | F39: . | I39: Czarna komnata profesora Tarantogi: Widowisko telewizyjne | L39: , | M39: s.83-107.
B40: - | D40: ~~~ | E40: 5 | F40: . | I40: Dziwny gość profesora Tarantogi: Widowisko telewizyjne | L40: , | M40: s.109-135.
B41: - | D41: ~~~ | E41: 6 | F41: . | I41: Przekładaniec: Scenariusz filmowy | L41: , | M41: s.137-154.
...

Sheet PLp
A1: ↗ | B1: Personalie Wydawnicze | C1: ( | D1: =RU!$I$1 -> RU | E1: ) | F1: → | G1: / | H1: 3 | I1: , | J1: 4 | K1: , | L1: 5 | M1: , | N1: 6 | O1: , | P1: 7 | Q1: , | R1: 8 | S1: , | T1: 9 | U1: , | V1: 10 | W1: , | X1: 11 | Y1: , | Z1: 12 | AA1: , | AB1: 13 | AC1: , | AD1: 14 | AE1: , | AF1: 15 | AG1: , | AH1: 16 | AI1: , | AJ1: 17 | AK1: , | AL1: 18 | AM1: , | AN1: 19 | AO1: , | AP1: 20 | AQ1: , | AR1: 21 | AS1: , | AT1: 22 | AU1: , | AV1: 23 | AW1: , | AX1: 24 | AY1: , | AZ1: 25
A2: 0 | B2: Część VI. Personalie Wydawnicze
A3: 0 | B3: Współautorzy, rozmówcy, tłumacze, świadkowie wypowiedzi, redaktorzy książek i specjalnych czasopismów z artykułami Stanisława Lema i o nim, autorzy artykułów o Stanisławie Lemie
A4: 12 | B4: Aldiss Brian W. | C4: – | D4: =CONCATENATE(About!A1,About!B58) -> A23 | E4: , | F4: =CONCATENATE(About!A1,About!B63) -> A26 | G4: ↗
A5: 34 | B5: Balcerzak Ewa | C5: – | D5: =CONCATENATE(About!A1,About!B48) -> A17 | E5: , | F5: =CONCATENATE(About!A1,About!B54) -> A20 | G5: ↗
A6: 35 | B6: Balcerzan Edward | C6: – | D6: =CONCATENATE(About!A1,About!B50) -> A18 | E6: , | F6: =CONCATENATE(About!A1,About!B58) -> A23
A7: 47 | B7: Barańczak Stanisław | C7: – | D7: =CONCATENATE(About!A1,About!B50) -> A18 | E7: , | F7: =CONCATENATE(About!A1,About!B87) -> A297 | G7: ↗
A8: 55 | B8: Bartoszewski Władysław | C8: – | D8: =CONCATENATE(LO!A1,LO!D16) -> L4 | E8: ↗
A9: 64 | B9: Bednarczyk Andrzej | C9: – | D9: =CONCATENATE(About!A1,About!B15) -> A10 | E9: ↗
A10: 70 | B10: Benford Gregory | C10: – | D10: =CONCATENATE(About!A1,About!B63) -> A26 | E10: ↗
A11: 73 | B11: Bereś Stanisław = Берес С. (BG), Бересь С. (RU,UK), Береш С. (BG,UK), Бэрэсь С. (BE), スタニスワフ・ベレシ (JA) | C11: – | D11: =CONCATENATE(About!A1,About!B87) -> A297 | E11: ↗
