Workbook

Sheet yaz-place-list
A1: city | B1: geonameid | L1: uri
A2: K. | B2: 3094802 | G2: =IFERROR(VLOOKUP(B2,data!$A:$J,10,FALSE()),"") -> E53_G96 | H2: =IFERROR(VLOOKUP(C2,data!$A:$J,10,FALSE()),"") | I2: =IFERROR(VLOOKUP(D2,data!$A:$J,10,FALSE()),"") | J2: =IFERROR(VLOOKUP(E2,data!$A:$J,10,FALSE()),"") | K2: =IFERROR(VLOOKUP(F2,data!$A:$J,10,FALSE()),"") | L2: =_xlfn.TEXTJOIN(" ",TRUE(),G2:K2) -> E53_G96
A3: K.: | B3: 3094802 | G3: =IFERROR(VLOOKUP(B3,data!$A:$J,10,FALSE()),"") -> E53_G96 | H3: =IFERROR(VLOOKUP(C3,data!$A:$J,10,FALSE()),"") | I3: =IFERROR(VLOOKUP(D3,data!$A:$J,10,FALSE()),"") | J3: =IFERROR(VLOOKUP(E3,data!$A:$J,10,FALSE()),"") | K3: =IFERROR(VLOOKUP(F3,data!$A:$J,10,FALSE()),"") | L3: =_xlfn.TEXTJOIN(" ",TRUE(),G3:K3) -> E53_G96
A4: Milano | B4: 3173435 | G4: =IFERROR(VLOOKUP(B4,data!$A:$J,10,FALSE()),"") -> E53_G121 | H4: =IFERROR(VLOOKUP(C4,data!$A:$J,10,FALSE()),"") | I4: =IFERROR(VLOOKUP(D4,data!$A:$J,10,FALSE()),"") | J4: =IFERROR(VLOOKUP(E4,data!$A:$J,10,FALSE()),"") | K4: =IFERROR(VLOOKUP(F4,data!$A:$J,10,FALSE()),"") | L4: =_xlfn.TEXTJOIN(" ",TRUE(),G4:K4) -> E53_G121
A5: N.Y. | B5: 5128581 | G5: =IFERROR(VLOOKUP(B5,data!$A:$J,10,FALSE()),"") -> E53_G130 | H5: =IFERROR(VLOOKUP(C5,data!$A:$J,10,FALSE()),"") | I5: =IFERROR(VLOOKUP(D5,data!$A:$J,10,FALSE()),"") | J5: =IFERROR(VLOOKUP(E5,data!$A:$J,10,FALSE()),"") | K5: =IFERROR(VLOOKUP(F5,data!$A:$J,10,FALSE()),"") | L5: =_xlfn.TEXTJOIN(" ",TRUE(),G5:K5) -> E53_G130
A6: W. | B6: 756135 | G6: =IFERROR(VLOOKUP(B6,data!$A:$J,10,FALSE()),"") -> E53_G218 | H6: =IFERROR(VLOOKUP(C6,data!$A:$J,10,FALSE()),"") | I6: =IFERROR(VLOOKUP(D6,data!$A:$J,10,FALSE()),"") | J6: =IFERROR(VLOOKUP(E6,data!$A:$J,10,FALSE()),"") | K6: =IFERROR(VLOOKUP(F6,data!$A:$J,10,FALSE()),"") | L6: =_xlfn.TEXTJOIN(" ",TRUE(),G6:K6) -> E53_G218
A7: Bucureşti | B7: 683506 | G7: =IFERROR(VLOOKUP(B7,data!$A:$J,10,FALSE()),"") -> E53_G29 | H7: =IFERROR(VLOOKUP(C7,data!$A:$J,10,FALSE()),"") | I7: =IFERROR(VLOOKUP(D7,data!$A:$J,10,FALSE()),"") | J7: =IFERROR(VLOOKUP(E7,data!$A:$J,10,FALSE()),"") | K7: =IFERROR(VLOOKUP(F7,data!$A:$J,10,FALSE()),"") | L7: =_xlfn.TEXTJOIN(" ",TRUE(),G7:K7) -> E53_G29
A8: İstanbul | B8: 745044 | G8: =IFERROR(VLOOKUP(B8,data!$A:$J,10,FALSE()),"") -> E53_G83 | H8: =IFERROR(VLOOKUP(C8,data!$A:$J,10,FALSE()),"") | I8: =IFERROR(VLOOKUP(D8,data!$A:$J,10,FALSE()),"") | J8: =IFERROR(VLOOKUP(E8,data!$A:$J,10,FALSE()),"") | K8: =IFERROR(VLOOKUP(F8,data!$A:$J,10,FALSE()),"") | L8: =_xlfn.TEXTJOIN(" ",TRUE(),G8:K8) -> E53_G83
A9: Essen | B9: 2928810 | G9: =IFERROR(VLOOKUP(B9,data!$A:$J,10,FALSE()),"") -> E53_G59 | H9: =IFERROR(VLOOKUP(C9,data!$A:$J,10,FALSE()),"") | I9: =IFERROR(VLOOKUP(D9,data!$A:$J,10,FALSE()),"") | J9: =IFERROR(VLOOKUP(E9,data!$A:$J,10,FALSE()),"") | K9: =IFERROR(VLOOKUP(F9,data!$A:$J,10,FALSE()),"") | L9: =_xlfn.TEXTJOIN(" ",TRUE(),G9:K9) -> E53_G59
A10: Rio de Janeiro | B10: 3451190 | G10: =IFERROR(VLOOKUP(B10,data!$A:$J,10,FALSE()),"") -> E53_G164 | H10: =IFERROR(VLOOKUP(C10,data!$A:$J,10,FALSE()),"") | I10: =IFERROR(VLOOKUP(D10,data!$A:$J,10,FALSE()),"") | J10: =IFERROR(VLOOKUP(E10,data!$A:$J,10,FALSE()),"") | K10: =IFERROR(VLOOKUP(F10,data!$A:$J,10,FALSE()),"") | L10: =_xlfn.TEXTJOIN(" ",TRUE(),G10:K10) -> E53_G164
A11: Amsterdam | B11: 2759794 | G11: =IFERROR(VLOOKUP(B11,data!$A:$J,10,FALSE()),"") -> E53_G2 | H11: =IFERROR(VLOOKUP(C11,data!$A:$J,10,FALSE()),"") | I11: =IFERROR(VLOOKUP(D11,data!$A:$J,10,FALSE()),"") | J11: =IFERROR(VLOOKUP(E11,data!$A:$J,10,FALSE()),"") | K11: =IFERROR(VLOOKUP(F11,data!$A:$J,10,FALSE()),"") | L11: =_xlfn.TEXTJOIN(" ",TRUE(),G11:K11) -> E53_G2
A12: Paris | B12: 2988507 | G12: =IFERROR(VLOOKUP(B12,data!$A:$J,10,FALSE()),"") -> E53_G148 | H12: =IFERROR(VLOOKUP(C12,data!$A:$J,10,FALSE()),"") | I12: =IFERROR(VLOOKUP(D12,data!$A:$J,10,FALSE()),"") | J12: =IFERROR(VLOOKUP(E12,data!$A:$J,10,FALSE()),"") | K12: =IFERROR(VLOOKUP(F12,data!$A:$J,10,FALSE()),"") | L12: =_xlfn.TEXTJOIN(" ",TRUE(),G12:K12) -> E53_G148
A13: F.a.M. | B13: 2925533 | G13: =IFERROR(VLOOKUP(B13,data!$A:$J,10,FALSE()),"") -> E53_G65 | H13: =IFERROR(VLOOKUP(C13,data!$A:$J,10,FALSE()),"") | I13: =IFERROR(VLOOKUP(D13,data!$A:$J,10,FALSE()),"") | J13: =IFERROR(VLOOKUP(E13,data!$A:$J,10,FALSE()),"") | K13: =IFERROR(VLOOKUP(F13,data!$A:$J,10,FALSE()),"") | L13: =_xlfn.TEXTJOIN(" ",TRUE(),G13:K13) -> E53_G65
... A15: Berlin | B15: 2950159 | G15: =IFERROR(VLOOKUP(B15,data!$A:$J,10,FALSE()),"") -> E53_G14 | H15: =IFERROR(VLOOKUP(C15,data!$A:$J,10,FALSE()),"") | I15: =IFERROR(VLOOKUP(D15,data!$A:$J,10,FALSE()),"") | J15: =IFERROR(VLOOKUP(E15,data!$A:$J,10,FALSE()),"") | K15: =IFERROR(VLOOKUP(F15,data!$A:$J,10,FALSE()),"") | L15: =_xlfn.TEXTJOIN(" ",TRUE(),G15:K15) -> E53_G14
A16: F.a.M., B. | B16: 2925533 | C16: 2950159 | G16: =IFERROR(VLOOKUP(B16,data!$A:$J,10,FALSE()),"") -> E53_G65 | H16: =IFERROR(VLOOKUP(C16,data!$A:$J,10,FALSE()),"") -> E53_G14 | I16: =IFERROR(VLOOKUP(D16,data!$A:$J,10,FALSE()),"") | J16: =IFERROR(VLOOKUP(E16,data!$A:$J,10,FALSE()),"") | K16: =IFERROR(VLOOKUP(F16,data!$A:$J,10,FALSE()),"") | L16: =_xlfn.TEXTJOIN(" ",TRUE(),G16:K16) -> E53_G65 E53_G14
A17: Stuttgart | B17: 2825297 | G17: =IFERROR(VLOOKUP(B17,data!$A:$J,10,FALSE()),"") -> E53_G187 | H17: =IFERROR(VLOOKUP(C17,data!$A:$J,10,FALSE()),"") | I17: =IFERROR(VLOOKUP(D17,data!$A:$J,10,FALSE()),"") | J17: =IFERROR(VLOOKUP(E17,data!$A:$J,10,FALSE()),"") | K17: =IFERROR(VLOOKUP(F17,data!$A:$J,10,FALSE()),"") | L17: =_xlfn.TEXTJOIN(" ",TRUE(),G17:K17) -> E53_G187
A18: Saarbrücken | B18: 2842647 | G18: =IFERROR(VLOOKUP(B18,data!$A:$J,10,FALSE()),"") -> E53_G170 | H18: =IFERROR(VLOOKUP(C18,data!$A:$J,10,FALSE()),"") | I18: =IFERROR(VLOOKUP(D18,data!$A:$J,10,FALSE()),"") | J18: =IFERROR(VLOOKUP(E18,data!$A:$J,10,FALSE()),"") | K18: =IFERROR(VLOOKUP(F18,data!$A:$J,10,FALSE()),"") | L18: =_xlfn.TEXTJOIN(" ",TRUE(),G18:K18) -> E53_G170
A19: Liverpool | B19: 2644210 | G19: =IFERROR(VLOOKUP(B19,data!$A:$J,10,FALSE()),"") -> E53_G104 | H19: =IFERROR(VLOOKUP(C19,data!$A:$J,10,FALSE()),"") | I19: =IFERROR(VLOOKUP(D19,data!$A:$J,10,FALSE()),"") | J19: =IFERROR(VLOOKUP(E19,data!$A:$J,10,FALSE()),"") | K19: =IFERROR(VLOOKUP(F19,data!$A:$J,10,FALSE()),"") | L19: =_xlfn.TEXTJOIN(" ",TRUE(),G19:K19) -> E53_G104
A20: Praha | B20: 3067696 | G20: =IFERROR(VLOOKUP(B20,data!$A:$J,10,FALSE()),"") -> E53_G157 | H20: =IFERROR(VLOOKUP(C20,data!$A:$J,10,FALSE()),"") | I20: =IFERROR(VLOOKUP(D20,data!$A:$J,10,FALSE()),"") | J20: =IFERROR(VLOOKUP(E20,data!$A:$J,10,FALSE()),"") | K20: =IFERROR(VLOOKUP(F20,data!$A:$J,10,FALSE()),"") | L20: =_xlfn.TEXTJOIN(" ",TRUE(),G20:K20) -> E53_G157
A21: Ljubljana | B21: 3196359 | G21: =IFERROR(VLOOKUP(B21,data!$A:$J,10,FALSE()),"") -> E53_G105 | H21: =IFERROR(VLOOKUP(C21,data!$A:$J,10,FALSE()),"") | I21: =IFERROR(VLOOKUP(D21,data!$A:$J,10,FALSE()),"") | J21: =IFERROR(VLOOKUP(E21,data!$A:$J,10,FALSE()),"") | K21: =IFERROR(VLOOKUP(F21,data!$A:$J,10,FALSE()),"") | L21: =_xlfn.TEXTJOIN(" ",TRUE(),G21:K21) -> E53_G105
A22: L. | B22: 2643743 | G22: =IFERROR(VLOOKUP(B22,data!$A:$J,10,FALSE()),"") -> E53_G107 | H22: =IFERROR(VLOOKUP(C22,data!$A:$J,10,FALSE()),"") | I22: =IFERROR(VLOOKUP(D22,data!$A:$J,10,FALSE()),"") | J22: =IFERROR(VLOOKUP(E22,data!$A:$J,10,FALSE()),"") | K22: =IFERROR(VLOOKUP(F22,data!$A:$J,10,FALSE()),"") | L22: =_xlfn.TEXTJOIN(" ",TRUE(),G22:K22) -> E53_G107
A23: Mem Martins | B23: 2266464 | G23: =IFERROR(VLOOKUP(B23,data!$A:$J,10,FALSE()),"") -> E53_G118 | H23: =IFERROR(VLOOKUP(C23,data!$A:$J,10,FALSE()),"") | I23: =IFERROR(VLOOKUP(D23,data!$A:$J,10,FALSE()),"") | J23: =IFERROR(VLOOKUP(E23,data!$A:$J,10,FALSE()),"") | K23: =IFERROR(VLOOKUP(F23,data!$A:$J,10,FALSE()),"") | L23: =_xlfn.TEXTJOIN(" ",TRUE(),G23:K23) -> E53_G118
A24: Buenos Aires | B24: 3435910 | G24: =IFERROR(VLOOKUP(B24,data!$A:$J,10,FALSE()),"") -> E53_G31 | H24: =IFERROR(VLOOKUP(C24,data!$A:$J,10,FALSE()),"") | I24: =IFERROR(VLOOKUP(D24,data!$A:$J,10,FALSE()),"") | J24: =IFERROR(VLOOKUP(E24,data!$A:$J,10,FALSE()),"") | K24: =IFERROR(VLOOKUP(F24,data!$A:$J,10,FALSE()),"") | L24: =_xlfn.TEXTJOIN(" ",TRUE(),G24:K24) -> E53_G31
A25: Tokyo / 東京 | B25: 1850147 | G25: =IFERROR(VLOOKUP(B25,data!$A:$J,10,FALSE()),"") -> E53_G203 | H25: =IFERROR(VLOOKUP(C25,data!$A:$J,10,FALSE()),"") | I25: =IFERROR(VLOOKUP(D25,data!$A:$J,10,FALSE()),"") | J25: =IFERROR(VLOOKUP(E25,data!$A:$J,10,FALSE()),"") | K25: =IFERROR(VLOOKUP(F25,data!$A:$J,10,FALSE()),"") | L25: =_xlfn.TEXTJOIN(" ",TRUE(),G25:K25) -> E53_G203
A26: Darmstadt, Niemcy | B26: 2938913 | G26: =IFERROR(VLOOKUP(B26,data!$A:$J,10,FALSE()),"") -> E53_G46 | H26: =IFERROR(VLOOKUP(C26,data!$A:$J,10,FALSE()),"") | I26: =IFERROR(VLOOKUP(D26,data!$A:$J,10,FALSE()),"") | J26: =IFERROR(VLOOKUP(E26,data!$A:$J,10,FALSE()),"") | K26: =IFERROR(VLOOKUP(F26,data!$A:$J,10,FALSE()),"") | L26: =_xlfn.TEXTJOIN(" ",TRUE(),G26:K26) -> E53_G46
A27: Cambridge, London | B27: 2653941 | C27: 2643743 | G27: =IFERROR(VLOOKUP(B27,data!$A:$J,10,FALSE()),"") -> E53_G36 | H27: =IFERROR(VLOOKUP(C27,data!$A:$J,10,FALSE()),"") -> E53_G107 | I27: =IFERROR(VLOOKUP(D27,data!$A:$J,10,FALSE()),"") | J27: =IFERROR(VLOOKUP(E27,data!$A:$J,10,FALSE()),"") | K27: =IFERROR(VLOOKUP(F27,data!$A:$J,10,FALSE()),"") | L27: =_xlfn.TEXTJOIN(" ",TRUE(),G27:K27) -> E53_G36 E53_G107
A28: Скопjе | B28: 785842 | G28: =IFERROR(VLOOKUP(B28,data!$A:$J,10,FALSE()),"") -> E53_G179 | H28: =IFERROR(VLOOKUP(C28,data!$A:$J,10,FALSE()),"") | I28: =IFERROR(VLOOKUP(D28,data!$A:$J,10,FALSE()),"") | J28: =IFERROR(VLOOKUP(E28,data!$A:$J,10,FALSE()),"") | K28: =IFERROR(VLOOKUP(F28,data!$A:$J,10,FALSE()),"") | L28: =_xlfn.TEXTJOIN(" ",TRUE(),G28:K28) -> E53_G179
A29: М. | B29: 524901 | G29: =IFERROR(VLOOKUP(B29,data!$A:$J,10,FALSE()),"") -> E53_G126 | H29: =IFERROR(VLOOKUP(C29,data!$A:$J,10,FALSE()),"") | I29: =IFERROR(VLOOKUP(D29,data!$A:$J,10,FALSE()),"") | J29: =IFERROR(VLOOKUP(E29,data!$A:$J,10,FALSE()),"") | K29: =IFERROR(VLOOKUP(F29,data!$A:$J,10,FALSE()),"") | L29: =_xlfn.TEXTJOIN(" ",TRUE(),G29:K29) -> E53_G126
A30: Минск | B30: 625144 | G30: =IFERROR(VLOOKUP(B30,data!$A:$J,10,FALSE()),"") -> E53_G123 | H30: =IFERROR(VLOOKUP(C30,data!$A:$J,10,FALSE()),"") | I30: =IFERROR(VLOOKUP(D30,data!$A:$J,10,FALSE()),"") | J30: =IFERROR(VLOOKUP(E30,data!$A:$J,10,FALSE()),"") | K30: =IFERROR(VLOOKUP(F30,data!$A:$J,10,FALSE()),"") | L30: =_xlfn.TEXTJOIN(" ",TRUE(),G30:K30) -> E53_G123
A31: Самара | B31: 499099 | G31: =IFERROR(VLOOKUP(B31,data!$A:$J,10,FALSE()),"") -> E53_G172 | H31: =IFERROR(VLOOKUP(C31,data!$A:$J,10,FALSE()),"") | I31: =IFERROR(VLOOKUP(D31,data!$A:$J,10,FALSE()),"") | J31: =IFERROR(VLOOKUP(E31,data!$A:$J,10,FALSE()),"") | K31: =IFERROR(VLOOKUP(F31,data!$A:$J,10,FALSE()),"") | L31: =_xlfn.TEXTJOIN(" ",TRUE(),G31:K31) -> E53_G172
A32: Пермь | B32: 511196 | G32: =IFERROR(VLOOKUP(B32,data!$A:$J,10,FALSE()),"") -> E53_G150 | H32: =IFERROR(VLOOKUP(C32,data!$A:$J,10,FALSE()),"") | I32: =IFERROR(VLOOKUP(D32,data!$A:$J,10,FALSE()),"") | J32: =IFERROR(VLOOKUP(E32,data!$A:$J,10,FALSE()),"") | K32: =IFERROR(VLOOKUP(F32,data!$A:$J,10,FALSE()),"") | L32: =_xlfn.TEXTJOIN(" ",TRUE(),G32:K32) -> E53_G150
A33: Абакан | B33: 1512236 | G33: =IFERROR(VLOOKUP(B33,data!$A:$J,10,FALSE()),"") -> E53_G1 | H33: =IFERROR(VLOOKUP(C33,data!$A:$J,10,FALSE()),"") | I33: =IFERROR(VLOOKUP(D33,data!$A:$J,10,FALSE()),"") | J33: =IFERROR(VLOOKUP(E33,data!$A:$J,10,FALSE()),"") | K33: =IFERROR(VLOOKUP(F33,data!$A:$J,10,FALSE()),"") | L33: =_xlfn.TEXTJOIN(" ",TRUE(),G33:K33) -> E53_G1
A34: Schweiz: Kanton Aargau | B34: 2661876 | G34: =IFERROR(VLOOKUP(B34,data!$A:$J,10,FALSE()),"") -> E53_G0 | H34: =IFERROR(VLOOKUP(C34,data!$A:$J,10,FALSE()),"") | I34: =IFERROR(VLOOKUP(D34,data!$A:$J,10,FALSE()),"") | J34: =IFERROR(VLOOKUP(E34,data!$A:$J,10,FALSE()),"") | K34: =IFERROR(VLOOKUP(F34,data!$A:$J,10,FALSE()),"") | L34: =_xlfn.TEXTJOIN(" ",TRUE(),G34:K34) -> E53_G0
A35: Warsaw | B35: 756135 | G35: =IFERROR(VLOOKUP(B35,data!$A:$J,10,FALSE()),"") -> E53_G218 | H35: =IFERROR(VLOOKUP(C35,data!$A:$J,10,FALSE()),"") | I35: =IFERROR(VLOOKUP(D35,data!$A:$J,10,FALSE()),"") | J35: =IFERROR(VLOOKUP(E35,data!$A:$J,10,FALSE()),"") | K35: =IFERROR(VLOOKUP(F35,data!$A:$J,10,FALSE()),"") | L35: =_xlfn.TEXTJOIN(" ",TRUE(),G35:K35) -> E53_G218
A36: Melbourne, Australia | B36: 2158177 | G36: =IFERROR(VLOOKUP(B36,data!$A:$J,10,FALSE()),"") -> E53_G117 | H36: =IFERROR(VLOOKUP(C36,data!$A:$J,10,FALSE()),"") | I36: =IFERROR(VLOOKUP(D36,data!$A:$J,10,FALSE()),"") | J36: =IFERROR(VLOOKUP(E36,data!$A:$J,10,FALSE()),"") | K36: =IFERROR(VLOOKUP(F36,data!$A:$J,10,FALSE()),"") | L36: =_xlfn.TEXTJOIN(" ",TRUE(),G36:K36) -> E53_G117
A37: Lublin | B37: 765876 | G37: =IFERROR(VLOOKUP(B37,data!$A:$J,10,FALSE()),"") -> E53_G108 | H37: =IFERROR(VLOOKUP(C37,data!$A:$J,10,FALSE()),"") | I37: =IFERROR(VLOOKUP(D37,data!$A:$J,10,FALSE()),"") | J37: =IFERROR(VLOOKUP(E37,data!$A:$J,10,FALSE()),"") | K37: =IFERROR(VLOOKUP(F37,data!$A:$J,10,FALSE()),"") | L37: =_xlfn.TEXTJOIN(" ",TRUE(),G37:K37) -> E53_G108
A38: München | B38: 2867714 | G38: =IFERROR(VLOOKUP(B38,data!$A:$J,10,FALSE()),"") -> E53_G127 | H38: =IFERROR(VLOOKUP(C38,data!$A:$J,10,FALSE()),"") | I38: =IFERROR(VLOOKUP(D38,data!$A:$J,10,FALSE()),"") | J38: =IFERROR(VLOOKUP(E38,data!$A:$J,10,FALSE()),"") | K38: =IFERROR(VLOOKUP(F38,data!$A:$J,10,FALSE()),"") | L38: =_xlfn.TEXTJOIN(" ",TRUE(),G38:K38) -> E53_G127
A39: Novi Sad | B39: 3194360 | G39: =IFERROR(VLOOKUP(B39,data!$A:$J,10,FALSE()),"") -> E53_G135 | H39: =IFERROR(VLOOKUP(C39,data!$A:$J,10,FALSE()),"") | I39: =IFERROR(VLOOKUP(D39,data!$A:$J,10,FALSE()),"") | J39: =IFERROR(VLOOKUP(E39,data!$A:$J,10,FALSE()),"") | K39: =IFERROR(VLOOKUP(F39,data!$A:$J,10,FALSE()),"") | L39: =_xlfn.TEXTJOIN(" ",TRUE(),G39:K39) -> E53_G135
... A42: Dresden | B42: 2935022 | G42: =IFERROR(VLOOKUP(B42,data!$A:$J,10,FALSE()),"") -> E53_G53 | H42: =IFERROR(VLOOKUP(C42,data!$A:$J,10,FALSE()),"") | I42: =IFERROR(VLOOKUP(D42,data!$A:$J,10,FALSE()),"") | J42: =IFERROR(VLOOKUP(E42,data!$A:$J,10,FALSE()),"") | K42: =IFERROR(VLOOKUP(F42,data!$A:$J,10,FALSE()),"") | L42: =_xlfn.TEXTJOIN(" ",TRUE(),G42:K42) -> E53_G53
A43: Warszawa, Chicago, Sydney, Dortmund, Paryż | B43: 756135 | C43: 4887398 | D43: 2147714 | E43: 2935517 | F43: 2988507 | G43: =IFERROR(VLOOKUP(B43,data!$A:$J,10,FALSE()),"") -> E53_G218 | H43: =IFERROR(VLOOKUP(C43,data!$A:$J,10,FALSE()),"") -> E53_G40 | I43: =IFERROR(VLOOKUP(D43,data!$A:$J,10,FALSE()),"") -> E53_G188 | J43: =IFERROR(VLOOKUP(E43,data!$A:$J,10,FALSE()),"") -> E53_G52 | K43: =IFERROR(VLOOKUP(F43,data!$A:$J,10,FALSE()),"") -> E53_G148 | L43: =_xlfn.TEXTJOIN(" ",TRUE(),G43:K43) -> E53_G218 E53_G40 E53_G188 E53_G52 E53_G148
...

Sheet data
A1: geonameid | B1: gn_city | C1: gn_country | D1: gn_city_pl | E1: wdid | F1: wd_city | G1: wd_country | H1: wd_city_pl | I1: nr | J1: uri
A2: 2661876 | B2: Aargau | C2: Switzerland | D2: Argowia | E2: Q11972 | F2: Canton of Aargau | G2: Switzerland | H2: Argowia | I2: 0 | J2: =_xlfn.CONCAT("E53_G",I2) -> E53_G0
A3: 1512236 | B3: Abakan | C3: Russia | D3: Abakan | E3: Q875 | F3: Abakan | G3: Russia | H3: Abakan | I3: =I2+1 -> 1 | J3: =_xlfn.CONCAT("E53_G",I3) -> E53_G1
A4: 2759794 | B4: Amsterdam | C4: The Netherlands | D4: Amsterdam | E4: Q727 | F4: Amsterdam | G4: Netherlands | H4: Amsterdam | I4: =I3+1 -> 2 | J4: =_xlfn.CONCAT("E53_G",I4) -> E53_G2
A5: 12514108 | B5: Arkaim | C5: Russia | D5: Arkaim | E5: Q672602 | F5: Arkaim | G5: Russia | H5: Arkaim | I5: =I4+1 -> 3 | J5: =_xlfn.CONCAT("E53_G",I5) -> E53_G3
A6: 162183 | B6: Ashgabat | C6: Turkmenistan | D6: Aszchabad | E6: Q23438 | F6: Ashgabat | G6: Turkmenistan | H6: Aszchabad | I6: =I5+1 -> 4 | J6: =_xlfn.CONCAT("E53_G",I6) -> E53_G4
A7: 264371 | B7: Athens | C7: Greece | D7: Ateny | E7: Q1524 | F7: Athens | G7: Greece | H7: Ateny | I7: =I6+1 -> 5 | J7: =_xlfn.CONCAT("E53_G",I7) -> E53_G5
A8: 587084 | B8: Baku | C8: Azerbaijan | D8: Baku | E8: Q9248 | F8: Baku | G8: Azerbaijan | H8: Baku | I8: =I7+1 -> 6 | J8: =_xlfn.CONCAT("E53_G",I8) -> E53_G6
A9: 4347778 | B9: Baltimore | C9: United States | D9: Baltimore | E9: Q5092 | F9: Baltimore | G9: United States | H9: Baltimore | I9: =I8+1 -> 7 | J9: =_xlfn.CONCAT("E53_G",I9) -> E53_G7
A10: 3061186 | B10: Banská Bystrica | C10: Slovakia | D10: Bańska Bystrzyca | E10: Q144983 | F10: Banská Bystrica | G10: Slovakia | H10: Bańska Bystrzyca | I10: =I9+1 -> 8 | J10: =_xlfn.CONCAT("E53_G",I10) -> E53_G8
A11: 3128760 | B11: Barcelona | C11: Spain | D11: Barcelona | E11: Q1492 | F11: Barcelona | G11: Spain | H11: Barcelona | I11: =I10+1 -> 9 | J11: =_xlfn.CONCAT("E53_G",I11) -> E53_G9
A12: 2656192 | B12: Basingstoke | C12: United Kingdom | D12: Basingstoke | E12: Q810196 | F12: Basingstoke | G12: United Kingdom | H12: Basingstoke | I12: =I11+1 -> 10 | J12: =_xlfn.CONCAT("E53_G",I12) -> E53_G10
A13: 615532 | B13: Batumi | C13: Georgia | D13: Batumi | E13: Q25475 | F13: Batumi | G13: Georgia | H13: Batumi | I13: =I12+1 -> 11 | J13: =_xlfn.CONCAT("E53_G",I13) -> E53_G11
A14: 1816670 | B14: Beijing | C14: China | D14: Pekin | E14: Q956 | F14: Beijing | G14: People's Republic of China | H14: Pekin | I14: =I13+1 -> 12 | J14: =_xlfn.CONCAT("E53_G",I14) -> E53_G12
... A235: 2657896 | B235: Zurich | C235: Switzerland | D235: Zurych | E235: Q72 | F235: Zurich | G235: Switzerland | H235: Zurych | I235: =I234+1 -> 233 | J235: =_xlfn.CONCAT("E53_G",I235) -> E53_G233
A236: 1526384 | E236: Q35493 | F236: Almaty | G236: Kazakhstan | H236: Ałmaty | I236: =I235+1 -> 234 | J236: =_xlfn.CONCAT("E53_G",I236) -> E53_G234
A237: 6557677 | E237: Q5274 | F237: Balve | G237: Germany | H237: Balve | I237: =I236+1 -> 235 | J237: =_xlfn.CONCAT("E53_G",I237) -> E53_G235
A238: 1510853 | E238: Q6014 | F238: Barnaul | G238: Russia | H238: Barnauł | I238: =I237+1 -> 236 | J238: =_xlfn.CONCAT("E53_G",I238) -> E53_G236
A239: 3202781 | E239: Q1012 | F239: Celje | G239: Slovenia | H239: Celje | I239: =I238+1 -> 237 | J239: =_xlfn.CONCAT("E53_G",I239) -> E53_G237
A240: 569154 | E240: Q5326 | F240: Cherkessk | G240: Russia | H240: Czerkiesk | I240: =I239+1 -> 238 | J240: =_xlfn.CONCAT("E53_G",I240) -> E53_G238
A241: 2025339 | E241: Q53139 | F241: Chita | G241: Russia | H241: Czyta | I241: =I240+1 -> 239 | J241: =_xlfn.CONCAT("E53_G",I241) -> E53_G239
A242: 774367 | E242: Q2330083 | F242: Chotomów | G242: Poland | H242: Chotomów | I242: =I241+1 -> 240 | J242: =_xlfn.CONCAT("E53_G",I242) -> E53_G240
A243: 2618425 | E243: Q1748 | F243: Copenhagen | G243: Denmark | H243: Kopenhaga | I243: =I242+1 -> 241 | J243: =_xlfn.CONCAT("E53_G",I243) -> E53_G241
A244: 2023469 | E244: Q6576 | F244: Irkutsk | G244: Russia | H244: Irkuck | I244: =I243+1 -> 242 | J244: =_xlfn.CONCAT("E53_G",I244) -> E53_G242
A245: 1503901 | E245: Q6066 | F245: Kemerovo | G245: Russia | H245: Kemerowo | I245: =I244+1 -> 243 | J245: =_xlfn.CONCAT("E53_G",I245) -> E53_G243
A246: 618426 | E246: Q21197 | F246: Chișinău | G246: Moldova | H246: Kiszyniów | I246: =I245+1 -> 244 | J246: =_xlfn.CONCAT("E53_G",I246) -> E53_G244
A247: 2774321 | E247: Q41753 | F247: Klagenfurt am Wörthersee | G247: Austria | H247: Klagenfurt am Wörthersee | I247: =I246+1 -> 245 | J247: =_xlfn.CONCAT("E53_G",I247) -> E53_G245
... A272: 616051 | E272: Q1953 | F272: Yerevan | G272: Armenia | H272: Erywań | I272: =I271+1 -> 270 | J272: =_xlfn.CONCAT("E53_G",I272) -> E53_G270

Sheet wiki-place
A1: city | B1: wd_city | C1: wd_country | D1: geonameid | E1: wdid | F1: uri
A2: Alma-Ata | B2: Almaty | C2: Kazakhstan | D2: 1526384 | E2: Q35493 | F2: =VLOOKUP(E2,data!E:J,6,FALSE()) -> E53_G234
A3: Amsterdam | B3: Amsterdam | C3: Netherlands | D3: 2759794 | E3: Q727 | F3: =VLOOKUP(E3,data!E:J,6,FALSE()) -> E53_G2
A4: Athens | B4: Athens | C4: Greece | D4: 264371 | E4: Q1524 | F4: =VLOOKUP(E4,data!E:J,6,FALSE()) -> E53_G5
A5: Baku | B5: Baku | C5: Azerbaijan | D5: 587081 | E5: Q9248 | F5: =VLOOKUP(E5,data!E:J,6,FALSE()) -> E53_G6
A6: Balve | B6: Balve | C6: Germany | D6: 6557677 | E6: Q5274 | F6: =VLOOKUP(E6,data!E:J,6,FALSE()) -> E53_G235
A7: Barcelona | B7: Barcelona | C7: Spain | D7: 6356055 | E7: Q1492 | F7: =VLOOKUP(E7,data!E:J,6,FALSE()) -> E53_G9
A8: Barnaul | B8: Barnaul | C8: Russia | D8: 1510853 | E8: Q6014 | F8: =VLOOKUP(E8,data!E:J,6,FALSE()) -> E53_G236
A9: Belgrade | B9: Belgrade | C9: Serbia | D9: 792680 | E9: Q3711 | F9: =VLOOKUP(E9,data!E:J,6,FALSE()) -> E53_G13
A10: Beriln | B10: Berlin | C10: Germany | D10: 2950159 | E10: Q64 | F10: =VLOOKUP(E10,data!E:J,6,FALSE()) -> E53_G14
A11: Berlin | B11: Berlin | C11: Germany | D11: 2950159 | E11: Q64 | F11: =VLOOKUP(E11,data!E:J,6,FALSE()) -> E53_G14
A12: Bialystok | B12: Białystok | C12: Poland | D12: 776069 | E12: Q761 | F12: =VLOOKUP(E12,data!E:J,6,FALSE()) -> E53_G15
A13: Białystok | B13: Białystok | C13: Poland | D13: 776069 | E13: Q761 | F13: =VLOOKUP(E13,data!E:J,6,FALSE()) -> E53_G15
... A127: Łódź | B127: Łódź | C127: Poland | D127: 3093133 | E127: Q580 | F127: =VLOOKUP(E127,data!E:J,6,FALSE()) -> E53_G106
